<?xml version='1.0' encoding='utf-8'?>
<robot name="robot_harambe_v04">
  <link name="urdf_base">
    <inertial>
      <origin xyz="0.071983 -0.000707749 -0.396794" rpy="0 0 0" />
      <mass value="5.734" />
      <inertia ixx="0.029089" ixy="1.00627e-06" ixz="1.93587e-05" iyy="0.0240807" iyz="-1.32561e-05" izz="0.0160144" />
    </inertial>
    <visual>
      <origin xyz="0.070373 -0.00470535 -0.431099" rpy="0 -1.57079 1.5708" />
      <geometry>
        <mesh filename="package://full_robot_description/meshes/visual/stator_x8_p20_120_unified.stl" />
      </geometry>
      <material name="stator_x8_p20_120_unified_material">
        <color rgba="0.882353 0.572549 0.478431 1" />
      </material>
    </visual>
    <visual>
      <origin xyz="0.070373 -0.000705351 -1.1821" rpy="0 0 -1.5708" />
      <geometry>
        <mesh filename="package://full_robot_description/meshes/visual/b_base.stl" />
      </geometry>
      <material name="b_base_material">
        <color rgba="0.980392 0.713725 0.00392157 1" />
      </material>
    </visual>
    <collision>
      <origin xyz="0.070373 -0.000705351 -1.1821" rpy="0 0 -1.5708" />
      <geometry>
        <mesh filename="package://full_robot_description/meshes/collision/b_base.stl" />
      </geometry>
    </collision>
    <visual>
      <origin xyz="0.070373 -0.000705351 0.319901" rpy="-3.14159 0 -1.5708" />
      <geometry>
        <mesh filename="package://full_robot_description/meshes/visual/plate_base_right.stl" />
      </geometry>
      <material name="plate_base_right_material">
        <color rgba="0.654902 0.823529 0.576471 1" />
      </material>
    </visual>
    <collision>
      <origin xyz="0.070373 -0.000705351 0.319901" rpy="-3.14159 0 -1.5708" />
      <geometry>
        <mesh filename="package://full_robot_description/meshes/collision/plate_base_right.stl" />
      </geometry>
    </collision>
    <visual>
      <origin xyz="0.070373 -0.000705351 0.599901" rpy="-3.14159 0 -1.5708" />
      <geometry>
        <mesh filename="package://full_robot_description/meshes/visual/spacer_pelvis_torso.stl" />
      </geometry>
      <material name="spacer_pelvis_torso_material">
        <color rgba="0.498039 0.498039 0.498039 1" />
      </material>
    </visual>
    <visual>
      <origin xyz="0.070373 -0.000705351 -1.1821" rpy="0 0 -1.5708" />
      <geometry>
        <mesh filename="package://full_robot_description/meshes/visual/f_base.stl" />
      </geometry>
      <material name="f_base_material">
        <color rgba="0.231373 0.380392 0.705882 1" />
      </material>
    </visual>
    <collision>
      <origin xyz="0.070373 -0.000705351 -1.1821" rpy="0 0 -1.5708" />
      <geometry>
        <mesh filename="package://full_robot_description/meshes/collision/f_base.stl" />
      </geometry>
    </collision>
    <visual>
      <origin xyz="0.070373 -0.000705351 -0.365099" rpy="0 0 -1.5708" />
      <geometry>
        <mesh filename="package://full_robot_description/meshes/visual/stator_x8_p20_120_unified.stl" />
      </geometry>
      <material name="stator_x8_p20_120_unified_2_material">
        <color rgba="0.882353 0.572549 0.478431 1" />
      </material>
    </visual>
    <visual>
      <origin xyz="0.070373 -0.000705351 -1.1821" rpy="0 0 -1.5708" />
      <geometry>
        <mesh filename="package://full_robot_description/meshes/visual/plate_base_left.stl" />
      </geometry>
      <material name="plate_base_left_material">
        <color rgba="0.764706 0.545098 0.803922 1" />
      </material>
    </visual>
    <collision>
      <origin xyz="0.070373 -0.000705351 -1.1821" rpy="0 0 -1.5708" />
      <geometry>
        <mesh filename="package://full_robot_description/meshes/collision/plate_base_left.stl" />
      </geometry>
    </collision>
    <visual>
      <origin xyz="0.070373 -0.000705351 -1.1821" rpy="0 0 -1.5708" />
      <geometry>
        <mesh filename="package://full_robot_description/meshes/visual/plate_base_top.stl" />
      </geometry>
      <material name="plate_base_top_material">
        <color rgba="0.654902 0.584314 0.823529 1" />
      </material>
    </visual>
    <collision>
      <origin xyz="0.070373 -0.000705351 -1.1821" rpy="0 0 -1.5708" />
      <geometry>
        <mesh filename="package://full_robot_description/meshes/collision/plate_base_top.stl" />
      </geometry>
    </collision>
    <visual>
      <origin xyz="0.070373 0.00329465 -0.431099" rpy="0 1.57079 1.5708" />
      <geometry>
        <mesh filename="package://full_robot_description/meshes/visual/stator_x8_p20_120_unified.stl" />
      </geometry>
      <material name="stator_x8_p20_120_unified_3_material">
        <color rgba="0.882353 0.572549 0.478431 1" />
      </material>
    </visual>
    <visual>
      <origin xyz="0.070373 -0.000705351 -0.431099" rpy="0 0 -1.5708" />
      <geometry>
        <mesh filename="package://full_robot_description/meshes/visual/jockstrap.stl" />
      </geometry>
      <material name="jockstrap_material">
        <color rgba="0.615686 0.811765 0.929412 1" />
      </material>
    </visual>
    <collision>
      <origin xyz="0.070373 -0.000705351 -0.431099" rpy="0 0 -1.5708" />
      <geometry>
        <mesh filename="package://full_robot_description/meshes/collision/jockstrap.stl" />
      </geometry>
    </collision>
  </link>
  <link name="urdf_simplified_torso">
    <inertial>
      <origin xyz="0.00199132 -4.19393e-05 0.328473" rpy="0 0 0" />
      <mass value="5.9" />
      <inertia ixx="0.318197" ixy="5.25211e-07" ixz="-0.00444278" iyy="0.294961" iyz="9.73773e-05" izz="0.0735035" />
    </inertial>
    <visual>
      <origin xyz="0 0 0.26095" rpy="0 0 -1.5708" />
      <geometry>
        <mesh filename="package://full_robot_description/meshes/visual/urdf_simplified_torso.stl" />
      </geometry>
      <material name="urdf_simplified_torso_material">
        <color rgba="0.647059 0.647059 0.647059 1" />
      </material>
    </visual>
    <collision>
      <origin xyz="0 0 0.26095" rpy="0 0 -1.5708" />
      <geometry>
        <mesh filename="package://full_robot_description/meshes/collision/urdf_simplified_torso.stl" />
      </geometry>
    </collision>
    <visual>
      <origin xyz="4.11536e-05 -0.000384166 0.6725" rpy="0 0 -1.5708" />
      <geometry>
        <mesh filename="package://full_robot_description/meshes/visual/head.stl" />
      </geometry>
      <material name="head_material">
        <color rgba="0.737255 0.937255 0.917647 1" />
      </material>
    </visual>
    <collision>
      <origin xyz="4.11536e-05 -0.000384166 0.6725" rpy="0 0 -1.5708" />
      <geometry>
        <mesh filename="package://full_robot_description/meshes/collision/head.stl" />
      </geometry>
    </collision>
    <visual>
      <origin xyz="4.11536e-05 -0.000384166 0.674428" rpy="0 0 -1.5708" />
      <geometry>
        <mesh filename="package://full_robot_description/meshes/visual/back_access.stl" />
      </geometry>
      <material name="back_access_material">
        <color rgba="0.231373 0.380392 0.705882 1" />
      </material>
    </visual>
  </link>
  <link name="urdf_l_shoulder_assembly">
    <inertial>
      <origin xyz="-0.00409836 0.0631966 -0.000544507" rpy="0 0 0" />
      <mass value="1.246" />
      <inertia ixx="0.00205876" ixy="-3.48871e-05" ixz="4.1195e-05" iyy="0.00152408" iyz="-7.63845e-06" izz="0.00171602" />
    </inertial>
    <visual>
      <origin xyz="-0.00129022 0.0502746 -0.000165439" rpy="0.122176 0 -1.5708" />
      <geometry>
        <mesh filename="package://full_robot_description/meshes/visual/l_shoulder.stl" />
      </geometry>
      <material name="l_shoulder_material">
        <color rgba="0.615686 0.811765 0.929412 1" />
      </material>
    </visual>
    <collision>
      <origin xyz="-0.00129022 0.0502746 -0.000165439" rpy="0.122176 0 -1.5708" />
      <geometry>
        <mesh filename="package://full_robot_description/meshes/collision/l_shoulder.stl" />
      </geometry>
    </collision>
    <visual>
      <origin xyz="-0.038213 0.07 -0.00469207" rpy="-1.44862 0 -1.5708" />
      <geometry>
        <mesh filename="package://full_robot_description/meshes/visual/stator_x6_p20_60_unified.stl" />
      </geometry>
      <material name="stator_x6_p20_60_unified_material">
        <color rgba="0.960784 0.835294 0.470588 1" />
      </material>
    </visual>
  </link>
  <link name="urdf_l_upper_arm_assembly">
    <inertial>
      <origin xyz="-0.0354438 0.0213187 -0.103332" rpy="0 0 0" />
      <mass value="0.802" />
      <inertia ixx="0.00190836" ixy="8.88428e-05" ixz="-0.000467525" iyy="0.00203106" iyz="0.000183116" izz="0.00107639" />
    </inertial>
    <visual>
      <origin xyz="-0.0268697 0.0182152 -0.0914675" rpy="0.14919 0.147554 -0.774351" />
      <geometry>
        <mesh filename="package://full_robot_description/meshes/visual/urdf_l_upper_arm_simplified.stl" />
      </geometry>
      <material name="urdf_l_upper_arm_simplified_material">
        <color rgba="0.917647 0.917647 0.917647 1" />
      </material>
    </visual>
    <collision>
      <origin xyz="-0.0268697 0.0182152 -0.0914675" rpy="0.14919 0.147554 -0.774351" />
      <geometry>
        <mesh filename="package://full_robot_description/meshes/collision/urdf_l_upper_arm_simplified.stl" />
      </geometry>
    </collision>
    <visual>
      <origin xyz="-0.046 0.0189203 -0.0890113" rpy="2.9924 0.147554 -2.36724" />
      <geometry>
        <mesh filename="package://full_robot_description/meshes/visual/stator_x4_p36_36_unified.stl" />
      </geometry>
      <material name="stator_x4_p36_36_unified_material">
        <color rgba="0.764706 0.545098 0.803922 1" />
      </material>
    </visual>
  </link>
  <link name="urdf_l_elbow_assembly">
    <inertial>
      <origin xyz="-0.004748 -0.00662541 -0.0710681" rpy="0 0 0" />
      <mass value="1.109" />
      <inertia ixx="0.00145153" ixy="5.51714e-05" ixz="-3.01713e-05" iyy="0.00147549" iyz="-7.59581e-05" izz="0.00114035" />
    </inertial>
    <visual>
      <origin xyz="-0.0245855 -0.0370918 -0.075" rpy="-1.57079 1.57079 -0.585341" />
      <geometry>
        <mesh filename="package://full_robot_description/meshes/visual/stator_x6_p20_60_unified.stl" />
      </geometry>
      <material name="stator_x6_p20_60_unified_2_material">
        <color rgba="0.960784 0.835294 0.470588 1" />
      </material>
    </visual>
    <visual>
      <origin xyz="-0.00676793 -0.0102107 -0.075" rpy="1.57079 1.57079 -0.585341" />
      <geometry>
        <mesh filename="package://full_robot_description/meshes/visual/urdf_l_elbow_simplified.stl" />
      </geometry>
      <material name="urdf_l_elbow_simplified_material">
        <color rgba="0.231373 0.380392 0.705882 1" />
      </material>
    </visual>
    <collision>
      <origin xyz="-0.00676793 -0.0102107 -0.075" rpy="1.57079 1.57079 -0.585341" />
      <geometry>
        <mesh filename="package://full_robot_description/meshes/collision/urdf_l_elbow_simplified.stl" />
      </geometry>
    </collision>
  </link>
  <link name="urdf_l_upper_forearm_assembly">
    <inertial>
      <origin xyz="0.0267132 -0.0286559 -0.0999185" rpy="0 0 0" />
      <mass value="0.707" />
      <inertia ixx="0.00162524" ixy="9.29307e-05" ixz="0.000226906" iyy="0.00146156" iyz="-0.000353662" izz="0.000776911" />
    </inertial>
    <visual>
      <origin xyz="0.0285991 -0.035 -0.115512" rpy="0.242704 0 -1.5708" />
      <geometry>
        <mesh filename="package://full_robot_description/meshes/visual/urdf_l_upper_forearm_simplified.stl" />
      </geometry>
      <material name="urdf_l_upper_forearm_simplified_material">
        <color rgba="0.498039 0.498039 0.498039 1" />
      </material>
    </visual>
    <collision>
      <origin xyz="0.0285991 -0.035 -0.115512" rpy="0.242704 0 -1.5708" />
      <geometry>
        <mesh filename="package://full_robot_description/meshes/collision/urdf_l_upper_forearm_simplified.stl" />
      </geometry>
    </collision>
    <visual>
      <origin xyz="0.0216296 -0.035 -0.0873622" rpy="-2.89889 0 -1.5708" />
      <geometry>
        <mesh filename="package://full_robot_description/meshes/visual/stator_x4_p36_36_unified.stl" />
      </geometry>
      <material name="stator_x4_p36_36_unified_2_material">
        <color rgba="0.764706 0.545098 0.803922 1" />
      </material>
    </visual>
  </link>
  <link name="urdf_l_lower_forearm_assembly">
    <inertial>
      <origin xyz="-0.00311766 0.00307025 -0.0515634" rpy="0 0 0" />
      <mass value="0.618" />
      <inertia ixx="0.000628386" ixy="-1.68351e-06" ixz="-2.8195e-05" iyy="0.000617293" iyz="-3.24981e-07" izz="0.000448744" />
    </inertial>
    <visual>
      <origin xyz="-0.00732538 0.00522865 -0.0615" rpy="-1.5708 0 0.95089" />
      <geometry>
        <mesh filename="package://full_robot_description/meshes/visual/urdf_l_lower_forearm_simplified.stl" />
      </geometry>
      <material name="urdf_l_lower_forearm_simplified_material">
        <color rgba="0.980392 0.713725 0.00392157 1" />
      </material>
    </visual>
    <collision>
      <origin xyz="-0.00732538 0.00522865 -0.0615" rpy="-1.5708 0 0.95089" />
      <geometry>
        <mesh filename="package://full_robot_description/meshes/collision/urdf_l_lower_forearm_simplified.stl" />
      </geometry>
    </collision>
    <visual>
      <origin xyz="-0.0305224 0.021786 -0.0615" rpy="1.5708 0 0.950885" />
      <geometry>
        <mesh filename="package://full_robot_description/meshes/visual/stator_x4_p36_36_unified.stl" />
      </geometry>
      <material name="stator_x4_p36_36_unified_3_material">
        <color rgba="0.764706 0.545098 0.803922 1" />
      </material>
    </visual>
  </link>
  <link name="urdf_l_wrist_assembly">
    <inertial>
      <origin xyz="-0.0219307 0.0106852 -0.0421315" rpy="0 0 0" />
      <mass value="0.098" />
      <inertia ixx="0.000100785" ixy="8.20205e-06" ixz="-3.2373e-05" iyy="0.000121426" iyz="6.79922e-06" izz="9.6353e-05" />
    </inertial>
    <visual>
      <origin xyz="-0.0219314 0.0106852 -0.0421315" rpy="0 0.248279 -1.5708" />
      <geometry>
        <mesh filename="package://full_robot_description/meshes/visual/l_wrist.stl" />
      </geometry>
      <material name="l_wrist_material">
        <color rgba="0.8 0.74902 0.913725 1" />
      </material>
    </visual>
    <collision>
      <origin xyz="-0.0219314 0.0106852 -0.0421315" rpy="0 0.248279 -1.5708" />
      <geometry>
        <mesh filename="package://full_robot_description/meshes/collision/l_wrist.stl" />
      </geometry>
    </collision>
  </link>
  <joint name="left_wrist_roll_joint_X4" type="revolute">
    <origin xyz="0.0219762 -0.0156859 -0.0615" rpy="-0.248279 0 -0.619909" />
    <parent link="urdf_l_lower_forearm_assembly" />
    <child link="urdf_l_wrist_assembly" />
    <axis xyz="1 0 0" />
    <limit effort="10" velocity="10" lower="-1.5708" upper="1.5708" />
  </joint>
  <joint name="left_wrist_yaw_joint_X4" type="revolute">
    <origin xyz="0.0391735 -0.035 -0.158223" rpy="-0.14286 -0.196878 0.634041" />
    <parent link="urdf_l_upper_forearm_assembly" />
    <child link="urdf_l_lower_forearm_assembly" />
    <axis xyz="0 0 1" />
    <limit effort="10" velocity="10" lower="-2.35619" upper="2.35619" />
  </joint>
  <joint name="left_elbow_pitch_joint_X6" type="revolute">
    <origin xyz="0.0193369 0.0291733 -0.075" rpy="0 -0.0190922 -0.585347" />
    <parent link="urdf_l_elbow_assembly" />
    <child link="urdf_l_upper_forearm_assembly" />
    <axis xyz="0 1 0" />
    <limit effort="10" velocity="10" lower="-1.309" upper="1.8326" />
  </joint>
  <joint name="left_shoulder_yaw_joint_X4" type="revolute">
    <origin xyz="-0.046 0.034306 -0.161394" rpy="0.209383 0.00530439 -0.024967" />
    <parent link="urdf_l_upper_arm_assembly" />
    <child link="urdf_l_elbow_assembly" />
    <axis xyz="0 0 1" />
    <limit effort="10" velocity="10" lower="-1.74533" upper="2.96706" />
  </joint>
  <joint name="left_shoulder_roll_joint_X6" type="revolute">
    <origin xyz="0.0456571 0.07 0.00560611" rpy="0 -0.122176 0" />
    <parent link="urdf_l_shoulder_assembly" />
    <child link="urdf_l_upper_arm_assembly" />
    <axis xyz="1 0 0" />
    <limit effort="10" velocity="10" lower="-0.20944" upper="2.93215" />
  </joint>
  <joint name="left_shoulder_pitch_joint_X6" type="revolute">
    <origin xyz="0 0.1695 0.423977" rpy="0 0 0" />
    <parent link="urdf_simplified_torso" />
    <child link="urdf_l_shoulder_assembly" />
    <axis xyz="0 1 0" />
    <limit effort="10" velocity="10" lower="-3.01942" upper="1.69297" />
  </joint>
  <link name="urdf_r_shoulder_assembly">
    <inertial>
      <origin xyz="-0.0047018 -0.0660727 -0.000602826" rpy="0 0 0" />
      <mass value="1.02" />
      <inertia ixx="0.0013257" ixy="1.37507e-05" ixz="2.16644e-05" iyy="0.00104972" iyz="3.46311e-06" izz="0.0011458" />
    </inertial>
    <visual>
      <origin xyz="-0.038213 -0.07 -0.00469207" rpy="-1.44862 0 -1.5708" />
      <geometry>
        <mesh filename="package://full_robot_description/meshes/visual/stator_x6_p20_60_unified.stl" />
      </geometry>
      <material name="stator_x6_p20_60_unified_3_material">
        <color rgba="0.960784 0.835294 0.470588 1" />
      </material>
    </visual>
    <visual>
      <origin xyz="-0.00128021 -0.0501448 -0.000164156" rpy="0.122176 0 -1.5708" />
      <geometry>
        <mesh filename="package://full_robot_description/meshes/visual/r_shoulder.stl" />
      </geometry>
      <material name="r_shoulder_material">
        <color rgba="0.615686 0.811765 0.929412 1" />
      </material>
    </visual>
    <collision>
      <origin xyz="-0.00128021 -0.0501448 -0.000164156" rpy="0.122176 0 -1.5708" />
      <geometry>
        <mesh filename="package://full_robot_description/meshes/collision/r_shoulder.stl" />
      </geometry>
    </collision>
  </link>
  <link name="urdf_r_upper_arm_assembly">
    <inertial>
      <origin xyz="-0.0347331 -0.0216398 -0.101809" rpy="0 0 0" />
      <mass value="0.802" />
      <inertia ixx="0.00188605" ixy="-9.73927e-05" ixz="-0.00045821" iyy="0.00200295" iyz="-0.000209822" izz="0.00106039" />
    </inertial>
    <visual>
      <origin xyz="-0.046 -0.0189197 -0.0890115" rpy="3.14159 -0.209436 -1.5708" />
      <geometry>
        <mesh filename="package://full_robot_description/meshes/visual/stator_x4_p36_36_unified.stl" />
      </geometry>
      <material name="stator_x4_p36_36_unified_4_material">
        <color rgba="0.764706 0.545098 0.803922 1" />
      </material>
    </visual>
    <visual>
      <origin xyz="-0.025543 -0.0188222 -0.0885532" rpy="0 -0.209436 -1.5708" />
      <geometry>
        <mesh filename="package://full_robot_description/meshes/visual/r_upper_arm.stl" />
      </geometry>
      <material name="r_upper_arm_material">
        <color rgba="0.231373 0.380392 0.705882 1" />
      </material>
    </visual>
    <collision>
      <origin xyz="-0.025543 -0.0188222 -0.0885532" rpy="0 -0.209436 -1.5708" />
      <geometry>
        <mesh filename="package://full_robot_description/meshes/collision/r_upper_arm.stl" />
      </geometry>
    </collision>
  </link>
  <link name="urdf_r_elbow_assembly">
    <inertial>
      <origin xyz="-0.00464628 0.00706688 -0.0612736" rpy="0 0 0" />
      <mass value="1.109" />
      <inertia ixx="0.00142737" ixy="-5.60371e-05" ixz="-3.53572e-05" iyy="0.00147543" iyz="4.92594e-05" izz="0.00111817" />
    </inertial>
    <visual>
      <origin xyz="0.000192865 -0.000269971 -0.0512953" rpy="0 0 -0.985455" />
      <geometry>
        <mesh filename="package://full_robot_description/meshes/visual/r_elbow.stl" />
      </geometry>
      <material name="r_elbow_material">
        <color rgba="0.796078 0.905882 0.745098 1" />
      </material>
    </visual>
    <collision>
      <origin xyz="0.000192865 -0.000269971 -0.0512953" rpy="0 0 -0.985455" />
      <geometry>
        <mesh filename="package://full_robot_description/meshes/collision/r_elbow.stl" />
      </geometry>
    </collision>
    <visual>
      <origin xyz="-0.0245856 0.0370918 -0.065" rpy="0.610863 -1.57079 1.54527" />
      <geometry>
        <mesh filename="package://full_robot_description/meshes/visual/stator_x6_p20_60_unified.stl" />
      </geometry>
      <material name="stator_x6_p20_60_unified_4_material">
        <color rgba="0.960784 0.835294 0.470588 1" />
      </material>
    </visual>
  </link>
  <link name="urdf_r_upper_forearm_assembly">
    <inertial>
      <origin xyz="0.0266786 0.0327896 -0.0982602" rpy="0 0 0" />
      <mass value="0.707" />
      <inertia ixx="0.00160609" ixy="-9.59596e-05" ixz="0.000238823" iyy="0.0014499" iyz="0.00033935" izz="0.000766591" />
    </inertial>
    <visual>
      <origin xyz="0.0216307 0.04 -0.0873619" rpy="-2.89888 0 -1.5708" />
      <geometry>
        <mesh filename="package://full_robot_description/meshes/visual/stator_x4_p36_36_unified.stl" />
      </geometry>
      <material name="stator_x4_p36_36_unified_5_material">
        <color rgba="0.764706 0.545098 0.803922 1" />
      </material>
    </visual>
    <visual>
      <origin xyz="0.0247724 0.0254856 -0.0806199" rpy="0.242722 0 -1.5708" />
      <geometry>
        <mesh filename="package://full_robot_description/meshes/visual/r_upper_forearm.stl" />
      </geometry>
      <material name="r_upper_forearm_material">
        <color rgba="0.890196 0.698039 0.639216 1" />
      </material>
    </visual>
    <collision>
      <origin xyz="0.0247724 0.0254856 -0.0806199" rpy="0.242722 0 -1.5708" />
      <geometry>
        <mesh filename="package://full_robot_description/meshes/collision/r_upper_forearm.stl" />
      </geometry>
    </collision>
  </link>
  <link name="urdf_r_lower_forearm_assembly">
    <inertial>
      <origin xyz="-0.00325453 -0.0023229 -0.046852" rpy="0 0 0" />
      <mass value="0.618" />
      <inertia ixx="0.000617744" ixy="-6.12409e-07" ixz="-3.11927e-05" iyy="0.000618165" iyz="-2.22632e-05" izz="0.000437775" />
    </inertial>
    <visual>
      <origin xyz="0.00167509 0.00119554 -0.0333447" rpy="0 0 -0.9509" />
      <geometry>
        <mesh filename="package://full_robot_description/meshes/visual/r_lower_forearm.stl" />
      </geometry>
      <material name="r_lower_forearm_material">
        <color rgba="0.941176 0.87451 0.678431 1" />
      </material>
    </visual>
    <collision>
      <origin xyz="0.00167509 0.00119554 -0.0333447" rpy="0 0 -0.9509" />
      <geometry>
        <mesh filename="package://full_robot_description/meshes/collision/r_lower_forearm.stl" />
      </geometry>
    </collision>
    <visual>
      <origin xyz="-0.0309297 -0.0220761 -0.0565" rpy="1.57079 0 2.19069" />
      <geometry>
        <mesh filename="package://full_robot_description/meshes/visual/stator_x4_p36_36_unified.stl" />
      </geometry>
      <material name="stator_x4_p36_36_unified_6_material">
        <color rgba="0.764706 0.545098 0.803922 1" />
      </material>
    </visual>
  </link>
  <link name="urdf_r_wrist_assembly">
    <inertial>
      <origin xyz="-0.0219123 -0.0106789 -0.0421059" rpy="0 0 0" />
      <mass value="0.15" />
      <inertia ixx="0.000154293" ixy="-1.25537e-05" ixz="-4.9547e-05" iyy="0.000185908" iyz="-1.03834e-05" izz="0.00014762" />
    </inertial>
    <visual>
      <origin xyz="-0.0219316 -0.0106852 -0.0421314" rpy="0 -0.248276 -1.5708" />
      <geometry>
        <mesh filename="package://full_robot_description/meshes/visual/r_wrist.stl" />
      </geometry>
      <material name="r_wrist_material">
        <color rgba="0.8 0.74902 0.913725 1" />
      </material>
    </visual>
    <collision>
      <origin xyz="-0.0219316 -0.0106852 -0.0421314" rpy="0 -0.248276 -1.5708" />
      <geometry>
        <mesh filename="package://full_robot_description/meshes/collision/r_wrist.stl" />
      </geometry>
    </collision>
  </link>
  <joint name="right_wrist_roll_joint_X4" type="revolute">
    <origin xyz="0.0219763 0.0156857 -0.0565" rpy="0.248276 0 0.619896" />
    <parent link="urdf_r_lower_forearm_assembly" />
    <child link="urdf_r_wrist_assembly" />
    <axis xyz="1 0 0" />
    <limit effort="10" velocity="10" lower="-1.65806" upper="1.65806" />
  </joint>
  <joint name="right_wrist_yaw_joint_X4" type="revolute">
    <origin xyz="0.0403774 0.04 -0.163076" rpy="0.142861 -0.196891 -0.634034" />
    <parent link="urdf_r_upper_forearm_assembly" />
    <child link="urdf_r_lower_forearm_assembly" />
    <axis xyz="0 0 1" />
    <limit effort="10" velocity="10" lower="-2.35619" upper="2.35619" />
  </joint>
  <joint name="right_elbow_pitch_joint_X6" type="revolute">
    <origin xyz="0.0220994 -0.033341 -0.065" rpy="0 -0.0190815 0.58534" />
    <parent link="urdf_r_elbow_assembly" />
    <child link="urdf_r_upper_forearm_assembly" />
    <axis xyz="0 1 0" />
    <limit effort="10" velocity="10" lower="-1.309" upper="1.8326" />
  </joint>
  <joint name="right_shoulder_yaw_joint_X4" type="revolute">
    <origin xyz="-0.046 -0.0353444 -0.166285" rpy="-0.20937 0.00530239 0.0249667" />
    <parent link="urdf_r_upper_arm_assembly" />
    <child link="urdf_r_elbow_assembly" />
    <axis xyz="0 0 1" />
    <limit effort="10" velocity="10" lower="-2.96706" upper="1.74533" />
  </joint>
  <joint name="right_shoulder_roll_joint_X6" type="revolute">
    <origin xyz="0.0456571 -0.07 0.00560611" rpy="0 -0.122176 0" />
    <parent link="urdf_r_shoulder_assembly" />
    <child link="urdf_r_upper_arm_assembly" />
    <axis xyz="1 0 0" />
    <limit effort="10" velocity="10" lower="-2.93215" upper="0.20944" />
  </joint>
  <joint name="right_shoulder_pitch_joint_X6" type="revolute">
    <origin xyz="0 -0.1695 0.423977" rpy="0 0 0" />
    <parent link="urdf_simplified_torso" />
    <child link="urdf_r_shoulder_assembly" />
    <axis xyz="0 1 0" />
    <limit effort="10" velocity="10" lower="-3.01942" upper="1.69297" />
  </joint>
  <joint name="waist_yaw_joint_X8" type="revolute">
    <origin xyz="0.070373 -0.000705351 -0.281099" rpy="0 0 0" />
    <parent link="urdf_base" />
    <child link="urdf_simplified_torso" />
    <axis xyz="0 0 1" />
    <limit effort="10" velocity="10" lower="-2.60054" upper="2.60054" />
  </joint>
  <link name="urdf_hip_assembly">
    <inertial>
      <origin xyz="-0.00387043 0.0602754 -3.33254e-05" rpy="0 0 0" />
      <mass value="1.829" />
      <inertia ixx="0.00318486" ixy="-1.248e-05" ixz="2.39579e-07" iyy="0.00257781" iyz="-3.95097e-06" izz="0.00266816" />
    </inertial>
    <visual>
      <origin xyz="0.03 0.062 0" rpy="1.57079 0 -1.5708" />
      <geometry>
        <mesh filename="package://full_robot_description/meshes/visual/hip.stl" />
      </geometry>
      <material name="hip_material">
        <color rgba="0.498039 0.498039 0.498039 1" />
      </material>
    </visual>
    <collision>
      <origin xyz="0.03 0.062 0" rpy="1.57079 0 -1.5708" />
      <geometry>
        <mesh filename="package://full_robot_description/meshes/collision/hip.stl" />
      </geometry>
    </collision>
    <visual>
      <origin xyz="-0.043 0.062 0" rpy="-1.57079 0 -1.5708" />
      <geometry>
        <mesh filename="package://full_robot_description/meshes/visual/stator_x8_p20_120_unified.stl" />
      </geometry>
      <material name="stator_x8_p20_120_unified_4_material">
        <color rgba="0.882353 0.572549 0.478431 1" />
      </material>
    </visual>
  </link>
  <link name="urdf_l_upper_femur_assembly">
    <inertial>
      <origin xyz="-0.0460989 0.000881037 -0.148514" rpy="0 0 0" />
      <mass value="1.93" />
      <inertia ixx="0.00524838" ixy="2.68214e-05" ixz="-0.000973448" iyy="0.00568591" iyz="1.37224e-06" izz="0.00347712" />
    </inertial>
    <visual>
      <origin xyz="0.571524 0.417098 -0.118" rpy="-0.981744 -1.57079 1.5708" />
      <geometry>
        <mesh filename="package://full_robot_description/meshes/visual/stopper_leg_28_75.stl" />
      </geometry>
      <material name="stopper_leg_28_75_material">
        <color rgba="0.972549 0.529412 0.00392157 1" />
      </material>
    </visual>
    <collision>
      <origin xyz="0.571524 0.417098 -0.118" rpy="-0.981744 -1.57079 1.5708" />
      <geometry>
        <mesh filename="package://full_robot_description/meshes/collision/stopper_leg_28_75.stl" />
      </geometry>
    </collision>
    <visual>
      <origin xyz="-0.0257799 0.00151622 -0.111785" rpy="0 0 -1.5708" />
      <geometry>
        <mesh filename="package://full_robot_description/meshes/visual/l_upper_femur.stl" />
      </geometry>
      <material name="l_upper_femur_material">
        <color rgba="0.141176 0.694118 0.65098 1" />
      </material>
    </visual>
    <collision>
      <origin xyz="-0.0257799 0.00151622 -0.111785" rpy="0 0 -1.5708" />
      <geometry>
        <mesh filename="package://full_robot_description/meshes/collision/l_upper_femur.stl" />
      </geometry>
    </collision>
    <visual>
      <origin xyz="-0.053 0 -0.124" rpy="3.14159 0 -1.5708" />
      <geometry>
        <mesh filename="package://full_robot_description/meshes/visual/stator_x8_p20_120_unified.stl" />
      </geometry>
      <material name="stator_x8_p20_120_unified_5_material">
        <color rgba="0.882353 0.572549 0.478431 1" />
      </material>
    </visual>
  </link>
  <link name="urdf_lower_femur_assembly">
    <inertial>
      <origin xyz="2.11243e-05 -0.00408754 -0.100571" rpy="0 0 0" />
      <mass value="1.832" />
      <inertia ixx="0.00401519" ixy="1.60501e-06" ixz="-3.40991e-06" iyy="0.00435606" iyz="-0.000112967" izz="0.00266245" />
    </inertial>
    <visual>
      <origin xyz="0.751 0.000165033 -0.1" rpy="-1.5708 1.57079 1.5708" />
      <geometry>
        <mesh filename="package://full_robot_description/meshes/visual/stopper_leg_22_5.stl" />
      </geometry>
      <material name="stopper_leg_22_5_material">
        <color rgba="0.768627 0.886275 0.952941 1" />
      </material>
    </visual>
    <collision>
      <origin xyz="0.751 0.000165033 -0.1" rpy="-1.5708 1.57079 1.5708" />
      <geometry>
        <mesh filename="package://full_robot_description/meshes/collision/stopper_leg_22_5.stl" />
      </geometry>
    </collision>
    <visual>
      <origin xyz="-4.57402e-09 0.00389134 -0.068766" rpy="0 0 -1.57079" />
      <geometry>
        <mesh filename="package://full_robot_description/meshes/visual/lower_femur.stl" />
      </geometry>
      <material name="lower_femur_material">
        <color rgba="0.380392 0.0470588 0.435294 1" />
      </material>
    </visual>
    <collision>
      <origin xyz="-4.57402e-09 0.00389134 -0.068766" rpy="0 0 -1.57079" />
      <geometry>
        <mesh filename="package://full_robot_description/meshes/collision/lower_femur.stl" />
      </geometry>
    </collision>
    <visual>
      <origin xyz="1.14104e-07 -0.043 -0.111" rpy="3.14159 -1.57079 1.5708" />
      <geometry>
        <mesh filename="package://full_robot_description/meshes/visual/stator_x8_p20_120_unified.stl" />
      </geometry>
      <material name="stator_x8_p20_120_unified_6_material">
        <color rgba="0.882353 0.572549 0.478431 1" />
      </material>
    </visual>
  </link>
  <link name="urdf_l_tibia_assembly">
    <inertial>
      <origin xyz="0.01449 -0.0488281 -0.199552" rpy="0 0 0" />
      <mass value="2.216" />
      <inertia ixx="0.0205548" ixy="0.000222702" ixz="0.00143905" iyy="0.0209762" iyz="-0.00195792" izz="0.00480101" />
    </inertial>
    <visual>
      <origin xyz="-0.018 -0.055 -0.16" rpy="-1.5708 0 -1.5708" />
      <geometry>
        <mesh filename="package://full_robot_description/meshes/visual/stator_x4_p36_36_unified.stl" />
      </geometry>
      <material name="stator_x4_p36_36_unified_7_material">
        <color rgba="0.764706 0.545098 0.803922 1" />
      </material>
    </visual>
    <visual>
      <origin xyz="-0.018 -0.055 -0.235" rpy="1.57079 0 1.5708" />
      <geometry>
        <mesh filename="package://full_robot_description/meshes/visual/stator_x4_p36_36_unified.stl" />
      </geometry>
      <material name="stator_x4_p36_36_unified_8_material">
        <color rgba="0.764706 0.545098 0.803922 1" />
      </material>
    </visual>
    <visual>
      <origin xyz="0.0845 -0.08222 -0.286965" rpy="0 -0.0174563 -1.5708" />
      <geometry>
        <mesh filename="package://full_robot_description/meshes/visual/m6_threaded_bar_300mm.stl" />
      </geometry>
      <material name="m6_threaded_bar_300mm_material">
        <color rgba="0.141176 0.0352941 0.396078 1" />
      </material>
    </visual>
    <visual>
      <origin xyz="0.05375 -0.055 -0.235" rpy="3.14159 0.0349063 -1.5708" />
      <geometry>
        <mesh filename="package://full_robot_description/meshes/visual/urdf_spacer_x4.stl" />
      </geometry>
      <material name="urdf_spacer_x4_material">
        <color rgba="0.615686 0.811765 0.929412 1" />
      </material>
    </visual>
    <visual>
      <origin xyz="0.000678721 -0.0431371 -0.186264" rpy="0 0 -1.5708" />
      <geometry>
        <mesh filename="package://full_robot_description/meshes/visual/urdf_l_tibia_assembly.stl" />
      </geometry>
      <material name="urdf_l_tibia_assembly_material">
        <color rgba="0.615686 0.811765 0.929412 1" />
      </material>
    </visual>
    <collision>
      <origin xyz="0.000678721 -0.0431371 -0.186264" rpy="0 0 -1.5708" />
      <geometry>
        <mesh filename="package://full_robot_description/meshes/collision/urdf_l_tibia_assembly.stl" />
      </geometry>
    </collision>
    <visual>
      <origin xyz="0.0845 -0.026877 -0.323993" rpy="0 0.0349063 -1.5708" />
      <geometry>
        <mesh filename="package://full_robot_description/meshes/visual/m6_threaded_bar_225mm.stl" />
      </geometry>
      <material name="m6_threaded_bar_225mm_material">
        <color rgba="0.27451 0.0117647 0.317647 1" />
      </material>
    </visual>
    <visual>
      <origin xyz="0.05375 -0.055 -0.16" rpy="0 0.0174563 1.5708" />
      <geometry>
        <mesh filename="package://full_robot_description/meshes/visual/urdf_spacer_x4.stl" />
      </geometry>
      <material name="urdf_spacer_x4_2_material">
        <color rgba="0.615686 0.811765 0.929412 1" />
      </material>
    </visual>
  </link>
  <link name="urdf_ankle_assembly">
    <inertial>
      <origin xyz="0 -0.004 -0.0125426" rpy="0 0 0" />
      <mass value="0.0818219" />
      <inertia ixx="1.69449e-05" ixy="-1.30849e-26" ixz="-4.29315e-17" iyy="2.15245e-05" iyz="-5.80972e-28" izz="1.25404e-05" />
    </inertial>
    <visual>
      <origin xyz="0 -0.004 -0.0125426" rpy="0 0 -1.5708" />
      <geometry>
        <mesh filename="package://full_robot_description/meshes/visual/urdf_ankle_assembly.stl" />
      </geometry>
      <material name="urdf_ankle_assembly_material">
        <color rgba="0.615686 0.811765 0.929412 1" />
      </material>
    </visual>
    <collision>
      <origin xyz="0 -0.004 -0.0125426" rpy="0 0 -1.5708" />
      <geometry>
        <mesh filename="package://full_robot_description/meshes/collision/urdf_ankle_assembly.stl" />
      </geometry>
    </collision>
  </link>
  <link name="urdf_foot_assembly">
    <inertial>
      <origin xyz="0.0436027 8.11114e-08 -0.0200314" rpy="0 0 0" />
      <mass value="0.309" />
      <inertia ixx="0.000232433" ixy="-1.58776e-11" ixz="-9.83566e-06" iyy="0.00121361" iyz="-6.57666e-10" izz="0.00137693" />
    </inertial>
    <visual>
      <origin xyz="0.0436027 7.24764e-08 -0.0200314" rpy="0 0 -1.5708" />
      <geometry>
        <mesh filename="package://full_robot_description/meshes/visual/urdf_foot_assembly.stl" />
      </geometry>
      <material name="urdf_foot_assembly_material">
        <color rgba="0.615686 0.811765 0.929412 1" />
      </material>
    </visual>
    <collision>
      <origin xyz="0.0436027 7.24764e-08 -0.0200314" rpy="0 0 -1.5708" />
      <geometry>
        <mesh filename="package://full_robot_description/meshes/collision/urdf_foot_assembly.stl" />
      </geometry>
    </collision>
  </link>
  <joint name="left_ankle_pitch_joint_X4" type="revolute">
    <origin xyz="0 -0.051 -0.395" rpy="0 0 0" />
    <parent link="urdf_l_tibia_assembly" />
    <child link="urdf_ankle_assembly" />
    <axis xyz="0 1 0" />
    <limit effort="10" velocity="10" lower="-0.785398" upper="0.785398" />
  </joint>
  <joint name="left_ankle_roll_joint_X4" type="revolute">
    <origin xyz="-0.012 -0.004 -0.028" rpy="0 0 0" />
    <parent link="urdf_ankle_assembly" />
    <child link="urdf_foot_assembly" />
    <axis xyz="1 0 0" />
    <limit effort="10" velocity="10" lower="-0.785398" upper="0.785398" />
  </joint>
  <joint name="left_knee_joint_X8" type="revolute">
    <origin xyz="-1.45947e-07 0.055 -0.111" rpy="0 0 0" />
    <parent link="urdf_lower_femur_assembly" />
    <child link="urdf_l_tibia_assembly" />
    <axis xyz="0 1 0" />
    <limit effort="10" velocity="10" lower="-1.52716" upper="1.52716" />
  </joint>
  <joint name="left_hip_yaw_joint_X8" type="revolute">
    <origin xyz="-0.053 0 -0.217" rpy="0 0 0" />
    <parent link="urdf_l_upper_femur_assembly" />
    <child link="urdf_lower_femur_assembly" />
    <axis xyz="0 0 1" />
    <limit effort="10" velocity="10" lower="-2.15199" upper="2.09003" />
  </joint>
  <joint name="left_hip_roll_joint_X8" type="revolute">
    <origin xyz="0.053 0.062 0" rpy="0 0 0" />
    <parent link="urdf_hip_assembly" />
    <child link="urdf_l_upper_femur_assembly" />
    <axis xyz="1 0 0" />
    <limit effort="10" velocity="10" lower="-0.383972" upper="3.22886" />
  </joint>
  <joint name="left_hip_pitch_joint_X8" type="revolute">
    <origin xyz="0.070373 0.0872946 -0.431099" rpy="0 0 0" />
    <parent link="urdf_base" />
    <child link="urdf_hip_assembly" />
    <axis xyz="0 1 0" />
    <limit effort="10" velocity="10" lower="-2.61799" upper="2.61799" />
  </joint>
  <link name="urdf_hip_assembly_2">
    <inertial>
      <origin xyz="-0.00387043 -0.0602754 3.33254e-05" rpy="0 0 0" />
      <mass value="1.829" />
      <inertia ixx="0.00318486" ixy="1.248e-05" ixz="-2.39579e-07" iyy="0.00257781" iyz="-3.95097e-06" izz="0.00266816" />
    </inertial>
    <visual>
      <origin xyz="0.03 -0.062 0" rpy="-1.5708 0 1.5708" />
      <geometry>
        <mesh filename="package://full_robot_description/meshes/visual/hip.stl" />
      </geometry>
      <material name="hip_2_material">
        <color rgba="0.498039 0.498039 0.498039 1" />
      </material>
    </visual>
    <collision>
      <origin xyz="0.03 -0.062 0" rpy="-1.5708 0 1.5708" />
      <geometry>
        <mesh filename="package://full_robot_description/meshes/collision/hip.stl" />
      </geometry>
    </collision>
    <visual>
      <origin xyz="-0.043 -0.062 0" rpy="1.5708 0 1.5708" />
      <geometry>
        <mesh filename="package://full_robot_description/meshes/visual/stator_x8_p20_120_unified.stl" />
      </geometry>
      <material name="stator_x8_p20_120_unified_7_material">
        <color rgba="0.882353 0.572549 0.478431 1" />
      </material>
    </visual>
  </link>
  <link name="urdf_r_upper_femur_assemby">
    <inertial>
      <origin xyz="-0.0457109 -0.000406025 -0.147969" rpy="0 0 0" />
      <mass value="1.912" />
      <inertia ixx="0.00512969" ixy="-1.22901e-06" ixz="-0.000930002" iyy="0.00557257" iyz="5.18759e-05" izz="0.00336728" />
    </inertial>
    <visual>
      <origin xyz="-0.0257799 -0.00151624 -0.111785" rpy="0 0 -1.5708" />
      <geometry>
        <mesh filename="package://full_robot_description/meshes/visual/r_upper_femur.stl" />
      </geometry>
      <material name="r_upper_femur_material">
        <color rgba="0.941176 0.87451 0.678431 1" />
      </material>
    </visual>
    <collision>
      <origin xyz="-0.0257799 -0.00151624 -0.111785" rpy="0 0 -1.5708" />
      <geometry>
        <mesh filename="package://full_robot_description/meshes/collision/r_upper_femur.stl" />
      </geometry>
    </collision>
    <visual>
      <origin xyz="-0.053 -1.478e-09 -0.124" rpy="3.14159 0 -1.5708" />
      <geometry>
        <mesh filename="package://full_robot_description/meshes/visual/stator_x8_p20_120_unified.stl" />
      </geometry>
      <material name="stator_x8_p20_120_unified_8_material">
        <color rgba="0.882353 0.572549 0.478431 1" />
      </material>
    </visual>
  </link>
  <link name="urdf_lower_femur_assembly_2">
    <inertial>
      <origin xyz="9.05521e-10 0.00357383 -0.101307" rpy="0 0 0" />
      <mass value="1.817" />
      <inertia ixx="0.00383469" ixy="-1.04286e-09" ixz="2.0768e-08" iyy="0.00421827" iyz="0.00019709" izz="0.00258541" />
    </inertial>
    <visual>
      <origin xyz="4.57402e-09 -0.00389134 -0.068766" rpy="0 0 1.5708" />
      <geometry>
        <mesh filename="package://full_robot_description/meshes/visual/lower_femur.stl" />
      </geometry>
      <material name="lower_femur_2_material">
        <color rgba="0.380392 0.0470588 0.435294 1" />
      </material>
    </visual>
    <collision>
      <origin xyz="4.57402e-09 -0.00389134 -0.068766" rpy="0 0 1.5708" />
      <geometry>
        <mesh filename="package://full_robot_description/meshes/collision/lower_femur.stl" />
      </geometry>
    </collision>
    <visual>
      <origin xyz="-1.14104e-07 0.043 -0.111" rpy="0 -1.57079 1.5708" />
      <geometry>
        <mesh filename="package://full_robot_description/meshes/visual/stator_x8_p20_120_unified.stl" />
      </geometry>
      <material name="stator_x8_p20_120_unified_9_material">
        <color rgba="0.882353 0.572549 0.478431 1" />
      </material>
    </visual>
  </link>
  <link name="urdf_r_tibia_assembly">
    <inertial>
      <origin xyz="0.0144959 0.0488304 -0.199574" rpy="0 0 0" />
      <mass value="2.215" />
      <inertia ixx="0.0205486" ixy="-0.000222584" ixz="0.00144134" iyy="0.0209705" iyz="0.00195651" izz="0.00479841" />
    </inertial>
    <visual>
      <origin xyz="0.05375 0.055 -0.16" rpy="3.14159 0.0174563 -1.5708" />
      <geometry>
        <mesh filename="package://full_robot_description/meshes/visual/urdf_spacer_x4.stl" />
      </geometry>
      <material name="urdf_spacer_x4_3_material">
        <color rgba="0.615686 0.811765 0.929412 1" />
      </material>
    </visual>
    <visual>
      <origin xyz="0.0845 0.0268696 -0.324206" rpy="0 -0.0349063 -1.5708" />
      <geometry>
        <mesh filename="package://full_robot_description/meshes/visual/m6_threaded_bar_225mm.stl" />
      </geometry>
      <material name="m6_threaded_bar_225mm_2_material">
        <color rgba="0.27451 0.0117647 0.317647 1" />
      </material>
    </visual>
    <visual>
      <origin xyz="0.05375 0.055 -0.235" rpy="0 0.0349063 1.5708" />
      <geometry>
        <mesh filename="package://full_robot_description/meshes/visual/urdf_spacer_x4.stl" />
      </geometry>
      <material name="urdf_spacer_x4_4_material">
        <color rgba="0.615686 0.811765 0.929412 1" />
      </material>
    </visual>
    <visual>
      <origin xyz="0.000678806 0.0431372 -0.186264" rpy="0 0 -1.5708" />
      <geometry>
        <mesh filename="package://full_robot_description/meshes/visual/urdf_r_tibia_assembly.stl" />
      </geometry>
      <material name="urdf_r_tibia_assembly_material">
        <color rgba="0.615686 0.811765 0.929412 1" />
      </material>
    </visual>
    <collision>
      <origin xyz="0.000678806 0.0431372 -0.186264" rpy="0 0 -1.5708" />
      <geometry>
        <mesh filename="package://full_robot_description/meshes/collision/urdf_r_tibia_assembly.stl" />
      </geometry>
    </collision>
    <visual>
      <origin xyz="-0.018 0.055 -0.16" rpy="-1.5708 0 -1.5708" />
      <geometry>
        <mesh filename="package://full_robot_description/meshes/visual/stator_x4_p36_36_unified.stl" />
      </geometry>
      <material name="stator_x4_p36_36_unified_9_material">
        <color rgba="0.764706 0.545098 0.803922 1" />
      </material>
    </visual>
    <visual>
      <origin xyz="0.0845 0.0822237 -0.287178" rpy="0 0.0174563 -1.5708" />
      <geometry>
        <mesh filename="package://full_robot_description/meshes/visual/m6_threaded_bar_300mm.stl" />
      </geometry>
      <material name="m6_threaded_bar_300mm_2_material">
        <color rgba="0.141176 0.0352941 0.396078 1" />
      </material>
    </visual>
    <visual>
      <origin xyz="-0.018 0.055 -0.235" rpy="1.57079 0 1.5708" />
      <geometry>
        <mesh filename="package://full_robot_description/meshes/visual/stator_x4_p36_36_unified.stl" />
      </geometry>
      <material name="stator_x4_p36_36_unified_10_material">
        <color rgba="0.764706 0.545098 0.803922 1" />
      </material>
    </visual>
  </link>
  <link name="urdf_ankle_assembly_2">
    <inertial>
      <origin xyz="0 -0.004 -0.0125426" rpy="0 0 0" />
      <mass value="0.0818219" />
      <inertia ixx="1.69449e-05" ixy="-2.22156e-26" ixz="4.29315e-17" iyy="2.15245e-05" iyz="3.73894e-27" izz="1.25404e-05" />
    </inertial>
    <visual>
      <origin xyz="0 -0.004 -0.0125426" rpy="0 0 -1.5708" />
      <geometry>
        <mesh filename="package://full_robot_description/meshes/visual/urdf_ankle_assembly.stl" />
      </geometry>
      <material name="urdf_ankle_assembly_2_material">
        <color rgba="0.615686 0.811765 0.929412 1" />
      </material>
    </visual>
    <collision>
      <origin xyz="0 -0.004 -0.0125426" rpy="0 0 -1.5708" />
      <geometry>
        <mesh filename="package://full_robot_description/meshes/collision/urdf_ankle_assembly.stl" />
      </geometry>
    </collision>
  </link>
  <link name="urdf_foot_assembly_2">
    <inertial>
      <origin xyz="0.0436027 8.11114e-08 -0.0200314" rpy="0 0 0" />
      <mass value="0.309" />
      <inertia ixx="0.000232433" ixy="-1.58776e-11" ixz="-9.83566e-06" iyy="0.00121361" iyz="-6.57666e-10" izz="0.00137693" />
    </inertial>
    <visual>
      <origin xyz="0.0436027 7.24764e-08 -0.0200314" rpy="0 0 -1.5708" />
      <geometry>
        <mesh filename="package://full_robot_description/meshes/visual/urdf_foot_assembly.stl" />
      </geometry>
      <material name="urdf_foot_assembly_2_material">
        <color rgba="0.615686 0.811765 0.929412 1" />
      </material>
    </visual>
    <collision>
      <origin xyz="0.0436027 7.24764e-08 -0.0200314" rpy="0 0 -1.5708" />
      <geometry>
        <mesh filename="package://full_robot_description/meshes/collision/urdf_foot_assembly.stl" />
      </geometry>
    </collision>
  </link>
  <joint name="right_ankle_pitch_joint_X4" type="revolute">
    <origin xyz="0 0.059 -0.395" rpy="0 0 0" />
    <parent link="urdf_r_tibia_assembly" />
    <child link="urdf_ankle_assembly_2" />
    <axis xyz="0 1 0" />
    <limit effort="10" velocity="10" lower="-0.785398" upper="0.785398" />
  </joint>
  <joint name="right_ankle_roll_joint_X4" type="revolute">
    <origin xyz="-0.012 -0.004 -0.028" rpy="0 0 0" />
    <parent link="urdf_ankle_assembly_2" />
    <child link="urdf_foot_assembly_2" />
    <axis xyz="1 0 0" />
    <limit effort="10" velocity="10" lower="-0.785398" upper="0.785398" />
  </joint>
  <joint name="right_knee_joint_X8" type="revolute">
    <origin xyz="1.45947e-07 -0.055 -0.111" rpy="0 0 0" />
    <parent link="urdf_lower_femur_assembly_2" />
    <child link="urdf_r_tibia_assembly" />
    <axis xyz="0 1 0" />
    <limit effort="10" velocity="10" lower="-1.52716" upper="1.52716" />
  </joint>
  <joint name="right_hip_yaw_joint_X8" type="revolute">
    <origin xyz="-0.053 0 -0.217" rpy="0 0 0" />
    <parent link="urdf_r_upper_femur_assemby" />
    <child link="urdf_lower_femur_assembly_2" />
    <axis xyz="0 0 1" />
    <limit effort="10" velocity="10" lower="-1.5708" upper="1.5708" />
  </joint>
  <joint name="right_hip_roll_joint_X8" type="revolute">
    <origin xyz="0.053 -0.062 0" rpy="0 0 0" />
    <parent link="urdf_hip_assembly_2" />
    <child link="urdf_r_upper_femur_assemby" />
    <axis xyz="1 0 0" />
    <limit effort="10" velocity="10" lower="-3.22886" upper="0.383972" />
  </joint>
  <joint name="right_hip_pitch_joint_X8" type="revolute">
    <origin xyz="0.070373 -0.0887054 -0.431099" rpy="0 0 0" />
    <parent link="urdf_base" />
    <child link="urdf_hip_assembly_2" />
    <axis xyz="0 1 0" />
    <limit effort="10" velocity="10" lower="-2.61799" upper="2.61799" />
  </joint>

  <!-- Pelvis IMU — attached to urdf_base -->
  <link name="pelvis_imu_link">
    <visual>
      <geometry><sphere radius="0.002" /></geometry>
    </visual>
  </link>
  <joint name="pelvis_imu_joint" type="fixed">
    <parent link="urdf_base" />
    <child link="pelvis_imu_link" />
    <origin rpy="3.141592653589793 -1.5707963267948966 0" xyz="0.1069 -0.0007 -0.4707" />
  </joint>
  <link name="pelvis_imu_sensor">
    <inertial>
      <mass value="0.0042339" />
      <origin rpy="0 0 0" xyz="0.0 0.0 -0.00374258" />
      <inertia ixx="0.00000019023" ixy="0.0" ixz="-0.00000002" iyy="0.00000024665" iyz="0.0" izz="0.00000027669" />
    </inertial>
  </link>
  <joint name="pelvis_imu_sensor_joint" type="fixed">
    <parent link="pelvis_imu_link" />
    <child link="pelvis_imu_sensor" />
    <origin rpy="0 0 0" xyz="0 0 0.003" />
  </joint>

  <!-- Torso IMU — attached to urdf_simplified_torso -->
  <link name="torso_imu_link">
    <visual>
      <geometry><sphere radius="0.002" /></geometry>
    </visual>
  </link>
  <joint name="torso_imu_joint" type="fixed">
    <parent link="urdf_simplified_torso" />
    <child link="torso_imu_link" />
    <origin rpy="0 1.5707963267948966 0" xyz="0.0635 0.0 0.35" />
  </joint>
  <link name="torso_imu_sensor">
    <inertial>
      <mass value="0.0042339" />
      <origin rpy="0 0 0" xyz="0.0 0.0 -0.00374258" />
      <inertia ixx="0.00000019023" ixy="0.0" ixz="-0.00000002" iyy="0.00000024665" iyz="0.0" izz="0.00000027669" />
    </inertial>
  </link>
  <joint name="torso_imu_sensor_joint" type="fixed">
    <parent link="torso_imu_link" />
    <child link="torso_imu_sensor" />
    <origin rpy="0 0 0" xyz="0 0 0.003" />
  </joint>
</robot>