<?xml version='1.0' encoding='utf-8'?>
<mujoco model="harambe_full_robot">
  <compiler angle="radian" />
  <asset>
    <mesh name="b_base" content_type="model/stl" file="package://full_robot_description/meshes/visual/b_base.stl" />
    <mesh name="f_base" content_type="model/stl" file="package://full_robot_description/meshes/collision/f_base.stl" />
    <mesh name="urdf_simplified_torso" content_type="model/stl" file="package://full_robot_description/meshes/visual/urdf_simplified_torso.stl" />
    <mesh name="head" content_type="model/stl" file="package://full_robot_description/meshes/collision/head.stl" />
    <mesh name="l_shoulder" content_type="model/stl" file="package://full_robot_description/meshes/collision/l_shoulder.stl" />
    <mesh name="urdf_l_upper_arm_simplified" content_type="model/stl" file="package://full_robot_description/meshes/visual/urdf_l_upper_arm_simplified.stl" />
    <mesh name="urdf_l_elbow_simplified" content_type="model/stl" file="package://full_robot_description/meshes/visual/urdf_l_elbow_simplified.stl" />
    <mesh name="urdf_l_upper_forearm_simplified" content_type="model/stl" file="package://full_robot_description/meshes/collision/urdf_l_upper_forearm_simplified.stl" />
    <mesh name="urdf_l_lower_forearm_simplified" content_type="model/stl" file="package://full_robot_description/meshes/collision/urdf_l_lower_forearm_simplified.stl" />
    <mesh name="l_wrist" content_type="model/stl" file="package://full_robot_description/meshes/visual/l_wrist.stl" />
    <mesh name="r_shoulder" content_type="model/stl" file="package://full_robot_description/meshes/collision/r_shoulder.stl" />
    <mesh name="r_upper_arm" content_type="model/stl" file="package://full_robot_description/meshes/collision/r_upper_arm.stl" />
    <mesh name="r_elbow" content_type="model/stl" file="package://full_robot_description/meshes/visual/r_elbow.stl" />
    <mesh name="r_upper_forearm" content_type="model/stl" file="package://full_robot_description/meshes/collision/r_upper_forearm.stl" />
    <mesh name="r_lower_forearm" content_type="model/stl" file="package://full_robot_description/meshes/visual/r_lower_forearm.stl" />
    <mesh name="r_wrist" content_type="model/stl" file="package://full_robot_description/meshes/collision/r_wrist.stl" />
    <mesh name="hip" content_type="model/stl" file="package://full_robot_description/meshes/collision/hip.stl" />
    <mesh name="l_upper_femur" content_type="model/stl" file="package://full_robot_description/meshes/visual/l_upper_femur.stl" />
    <mesh name="lower_femur" content_type="model/stl" file="package://full_robot_description/meshes/visual/lower_femur.stl" />
    <mesh name="urdf_l_tibia_assembly" content_type="model/stl" file="package://full_robot_description/meshes/collision/urdf_l_tibia_assembly.stl" />
    <mesh name="urdf_ankle_assembly" content_type="model/stl" file="package://full_robot_description/meshes/visual/urdf_ankle_assembly.stl" />
    <mesh name="urdf_foot_assembly" content_type="model/stl" file="package://full_robot_description/meshes/visual/urdf_foot_assembly.stl" />
    <mesh name="r_upper_femur" content_type="model/stl" file="package://full_robot_description/meshes/visual/r_upper_femur.stl" />
    <mesh name="urdf_r_tibia_assembly" content_type="model/stl" file="package://full_robot_description/meshes/collision/urdf_r_tibia_assembly.stl" />
    <mesh name="low_res_bno055_imu" content_type="model/stl" file="package://imu_description/meshes/low_res_bno055_imu.stl" />
  </asset>
  <worldbody>
    <body name="urdf_base" pos="0 0 1.24">
      <inertial pos="0.0334604 -0.000699269 -0.431702" mass="5.132" diaginertia="0.0288848 0.0213139 0.0155352" />
      <freejoint name="root" />
      <geom pos="-0.00271429 -0.000697952 -0.432504" quat="0.707105 0 0 -0.707108" type="mesh" rgba="0.368627 0.25098 0.643137 1" mesh="b_base" />
      <geom pos="0.070373 -0.000705351 -0.431099" quat="0.707105 0 0 -0.707108" type="mesh" rgba="0.909804 0.572549 0.164706 1" mesh="f_base" />
      <body name="urdf_simplified_torso" pos="0.0333787 -0.000698852 -0.300748">
        <inertial pos="0.00209319 -4.17161e-05 0.327223" quat="0.999959 0.000222179 0.00902541 -2.61927e-05" mass="5.90847" diaginertia="0.321444 0.295277 0.0774427" />
        <joint name="waist_yaw_joint_X8" pos="0 0 0" axis="0 0 1" range="-1.57 1.57" armature="0.01" damping="0.5" />
        <geom pos="0 0 0.26095" quat="0.707105 0 0 -0.707108" type="mesh" rgba="0.647059 0.647059 0.647059 1" mesh="urdf_simplified_torso" />
        <geom pos="4.03711e-05 -0.000382221 0.67095" quat="0.707105 0 0 -0.707108" type="mesh" rgba="0.737255 0.937255 0.917647 1" mesh="head" />
        <geom pos="0.0705 0 -0.17" quat="0 -0.707107 0 0.707107" type="mesh" rgba="0.2 0.2 0.2 1" mesh="low_res_bno055_imu" />
        <geom pos="0.0665 0 0.35" quat="0.707107 0 0.707107 0" type="mesh" rgba="0.2 0.2 0.2 1" mesh="low_res_bno055_imu" />
        <body name="urdf_l_shoulder_assembly" pos="0 0.1755 0.423977">
          <inertial pos="-0.00409836 0.0631966 -0.000544496" quat="0.697622 0.713265 -0.0648222 0.0193628" mass="1.246" diaginertia="0.00206597 0.0017112 0.00152169" />
          <joint name="left_shoulder_pitch_joint_X6" pos="0 0 0" axis="0 1 0" range="-3.02 1.69" armature="0.01" damping="0.5" />
          <geom pos="-0.00129022 0.0502746 -0.000165436" quat="0.705787 0.0431681 -0.0431683 -0.705789" type="mesh" rgba="0.615686 0.811765 0.929412 1" mesh="l_shoulder" />
          <body name="urdf_l_upper_arm_assembly" pos="0.0456571 0.07 0.00560599" quat="0.998135 0 -0.0610485 0">
            <inertial pos="-0.0354438 0.0213179 -0.103332" quat="0.973759 0.0936596 0.204078 0.0370533" mass="0.802" diaginertia="0.00211885 0.0020649 0.000832061" />
            <joint name="left_shoulder_roll_joint_X6" pos="0 0 0" axis="1 0 0" range="-0.21 2.93" armature="0.01" damping="0.5" />
            <geom pos="-0.0268697 0.0182146 -0.0914677" quat="0.918818 0.0965719 0.0399998 -0.380587" type="mesh" rgba="0.917647 0.917647 0.917647 1" mesh="urdf_l_upper_arm_simplified" />
            <body name="urdf_l_elbow_assembly" pos="-0.046 0.0343048 -0.161394" quat="0.994441 0.104521 0.0013329 -0.0126916">
              <inertial pos="-0.00454375 -0.00631726 -0.0710681" quat="0.887194 -0.0766275 0.0688607 0.449748" mass="1.109" diaginertia="0.00153484 0.00140612 0.00112093" />
              <joint name="left_shoulder_yaw_joint_X4" pos="0 0 0" axis="0 0 1" range="-1.75 2.97" armature="0.01" damping="0.5" />
              <geom pos="-0.00676793 -0.0102107 -0.075" quat="0.334487 0.622994 0.334483 -0.622992" type="mesh" rgba="0.231373 0.380392 0.705882 1" mesh="urdf_l_elbow_simplified" />
              <body name="urdf_l_upper_forearm_assembly" pos="0.019337 0.0291733 -0.075" quat="0.957432 -0.00275385 -0.00913906 -0.2885">
                <inertial pos="0.0267134 -0.0286559 -0.0999185" quat="0.973929 -0.195153 -0.115628 0.00283339" mass="0.707" diaginertia="0.00168233 0.00161132 0.000570063" />
                <joint name="left_elbow_pitch_joint_X6" pos="0 0 0" axis="0 1 0" range="-1.31 1.83" armature="0.01" damping="0.5" />
                <geom pos="0.0285993 -0.035 -0.115512" quat="0.701905 0.0855989 -0.0855992 -0.701908" type="mesh" rgba="0.498039 0.498039 0.498039 1" mesh="urdf_l_upper_forearm_simplified" />
                <body name="urdf_l_lower_forearm_assembly" pos="0.0391738 -0.035 -0.158223" quat="0.945344 -0.0369253 -0.115286 0.302772">
                  <inertial pos="-0.00311766 0.00307025 -0.0515634" quat="0.995785 -0.00558184 0.0757942 -0.0513421" mass="0.618" diaginertia="0.000632875 0.000617128 0.000444421" />
                  <joint name="left_wrist_yaw_joint_X4" pos="0 0 0" axis="0 0 1" range="-2.36 2.36" armature="0.01" damping="0.5" />
                  <geom pos="-0.00732538 0.00522865 -0.0615" quat="0.62868 -0.628682 -0.323668 0.323666" type="mesh" rgba="0.980392 0.713725 0.00392157 1" mesh="urdf_l_lower_forearm_simplified" />
                  <body name="urdf_l_wrist_assembly" pos="0.0219762 -0.0156859 -0.0615" quat="0.945019 -0.117917 0.0377661 -0.302668">
                    <inertial pos="-0.0350691 -0.00329837 -0.0492438" quat="0.605731 0.722362 -0.236803 0.234961" mass="0.28979" diaginertia="0.00243123 0.00233604 0.00042858" />
                    <joint name="left_wrist_roll_joint_X4" pos="0 0 0" axis="1 0 0" range="-1.57 1.57" armature="0.01" damping="0.5" />
                    <geom pos="-0.0219314 0.0106848 -0.0421315" quat="0.701664 0.087552 0.0875516 -0.701667" type="mesh" rgba="0.8 0.74902 0.913725 1" mesh="l_wrist" />
                    <geom size="0.028 0.0139" pos="-0.034 0.0183419 -0.073183" quat="-0.0566745 0.454209 0.882249 0.110086" type="cylinder" />
                    <geom size="0.01955 0.0101 0.0287" pos="-0.032141 0.0218129 -0.0974749" quat="0.281098 0.36125 0.546004 0.701685" type="box" />
                    <geom size="0.01955 0.02 0.0407" pos="-0.0321411 0.0292339 -0.126749" quat="0.281098 0.36125 0.546004 0.701685" type="box" />
                    <geom size="0.0161 0.02 0.0407" pos="-0.0340003 0.0415631 -0.164786" quat="0.281098 0.36125 0.546004 0.701685" type="box" />
                    <geom size="0.00625 0.00555 0.00445" pos="-0.0582213 0.0292636 -0.194623" quat="0.281098 0.36125 0.546004 0.701685" type="box" />
                    <geom size="0.00625 0.00555 0.00445" pos="-0.0426752 0.0400198 -0.191896" quat="0.281098 0.36125 0.546004 0.701685" type="box" />
                    <geom size="0.00625 0.00555 0.00445" pos="-0.0273734 0.0506071 -0.189212" quat="0.281098 0.36125 0.546004 0.701685" type="box" />
                    <geom size="0.00625 0.00555 0.00445" pos="-0.0117459 0.0614196 -0.186471" quat="0.281098 0.36125 0.546004 0.701685" type="box" />
                    <geom size="0.0075 0.006 0.007" pos="-0.00285156 0.0304218 -0.120155" quat="-0.117918 0.945019 0.302668 0.0377638" type="box" />
                    <geom size="0.025 0.015 0.008" pos="0.0226552 0.0452624 -0.127844" quat="0.598599 0.769278 0.13717 0.176278" type="box" />
                    <geom size="0.0125 0.007 0.007" pos="0.0516123 0.0644116 -0.147288" quat="0.598599 0.769278 0.13717 0.176278" type="box" />
                    <geom size="0.012 0.008 0.006" pos="0.0697528 0.0768567 -0.159769" quat="0.598599 0.769278 0.13717 0.176278" type="box" />
                    <geom size="0.007 0.016 0.006" pos="-0.0129662 0.0681228 -0.202032" quat="0.28736 0.356289 0.533675 0.711107" type="box" />
                    <geom size="0.007 0.021 0.005" pos="-0.0103677 0.0761462 -0.239203" quat="0.28736 0.356289 0.533675 0.711107" type="box" />
                    <geom size="0.007 0.016 0.006" pos="-0.0290904 0.0570573 -0.205218" quat="0.281098 0.36125 0.546004 0.701685" type="box" />
                    <geom size="0.007 0.023 0.005" pos="-0.0276829 0.0649848 -0.244516" quat="0.281098 0.36125 0.546004 0.701685" type="box" />
                    <geom size="0.007 0.016 0.006" pos="-0.0453378 0.0456873 -0.20756" quat="0.271546 0.368485 0.564185 0.687152" type="box" />
                    <geom size="0.007 0.021 0.005" pos="-0.0455508 0.0519894 -0.245153" quat="0.271546 0.368485 0.564185 0.687152" type="box" />
                    <geom size="0.007 0.016 0.006" pos="-0.0615406 0.0340908 -0.20888" quat="0.261807 0.375467 0.581979 0.672148" type="box" />
                    <geom size="0.007 0.017 0.005" pos="-0.0636102 0.0392832 -0.242489" quat="0.261807 0.375467 0.581979 0.672148" type="box" />
                  </body>
                </body>
              </body>
            </body>
          </body>
        </body>
        <body name="urdf_r_shoulder_assembly" pos="0 -0.1755 0.423977">
          <inertial pos="-0.0047018 -0.0660727 -0.000602814" quat="0.713437 0.697755 -0.0247317 0.0594384" mass="1.02" diaginertia="0.00132898 0.00114326 0.00104898" />
          <joint name="right_shoulder_pitch_joint_X6" pos="0 0 0" axis="0 1 0" range="-3.02 1.69" armature="0.01" damping="0.5" />
          <geom pos="-0.00128021 -0.0501448 -0.000164153" quat="0.705787 0.0431681 -0.0431683 -0.705789" type="mesh" rgba="0.615686 0.811765 0.929412 1" mesh="r_shoulder" />
          <body name="urdf_r_upper_arm_assembly" pos="0.0456571 -0.07 0.00560599" quat="0.998135 0 -0.0610485 0">
            <inertial pos="-0.0347331 -0.0216406 -0.101809" quat="0.973583 -0.102329 0.203 -0.0213396" mass="0.802" diaginertia="0.00209028 0.00204755 0.00081156" />
            <joint name="right_shoulder_roll_joint_X6" pos="0 0 0" axis="1 0 0" range="-2.93 0.21" armature="0.01" damping="0.5" />
            <geom pos="-0.025543 -0.0188228 -0.088553" quat="0.703232 -0.0739145 -0.0739142 -0.703234" type="mesh" rgba="0.231373 0.380392 0.705882 1" mesh="r_upper_arm" />
            <body name="urdf_r_elbow_assembly" pos="-0.046 -0.0353456 -0.166285" quat="0.994441 -0.104522 0.00133209 0.0126914">
              <inertial pos="-0.00464629 0.00706688 -0.0612736" quat="0.471332 0.0675355 -0.0316928 0.878795" mass="1.109" diaginertia="0.00152148 0.00139045 0.00110905" />
              <joint name="right_shoulder_yaw_joint_X4" pos="0 0 0" axis="0 0 1" range="-2.97 1.75" armature="0.01" damping="0.5" />
              <geom pos="0.000192865 -0.000269971 -0.0512953" quat="0.881046 0 0 -0.47303" type="mesh" rgba="0.796078 0.905882 0.745098 1" mesh="r_elbow" />
              <body name="urdf_r_upper_forearm_assembly" pos="0.0220994 -0.0333409 -0.065" quat="0.957433 0.0027535 -0.00913802 0.288497">
                <inertial pos="0.026678 0.0327896 -0.0982604" quat="0.974066 0.190904 -0.121054 -0.00984866" mass="0.707" diaginertia="0.00166966 0.00158973 0.000563186" />
                <joint name="right_elbow_pitch_joint_X6" pos="0 0 0" axis="0 1 0" range="-1.31 1.83" armature="0.01" damping="0.5" />
                <geom pos="0.0247718 0.0254856 -0.0806201" quat="0.701905 0.0856024 -0.0856027 -0.701907" type="mesh" rgba="0.890196 0.698039 0.639216 1" mesh="r_upper_forearm" />
                <body name="urdf_r_lower_forearm_assembly" pos="0.0403763 0.04 -0.163076" quat="0.945345 0.0369231 -0.115288 -0.302768">
                  <inertial pos="-0.00325453 -0.0023229 -0.046852" quat="0.94751 -0.0307144 0.0959044 0.303454" mass="0.618" diaginertia="0.000625145 0.000618602 0.000429937" />
                  <joint name="right_wrist_yaw_joint_X4" pos="0 0 0" axis="0 0 1" range="-2.36 2.36" armature="0.01" damping="0.5" />
                  <geom pos="0.00167509 0.00119555 -0.0333447" quat="0.889087 0 0 -0.457739" type="mesh" rgba="0.941176 0.87451 0.678431 1" mesh="r_lower_forearm" />
                  <body name="urdf_r_wrist_assembly" pos="0.0219763 0.0156857 -0.0565" quat="0.94502 0.117922 0.0377669 0.302662">
                    <inertial pos="-0.0192017 -0.0201323 -0.0432124" quat="0.41953 0.30737 -0.670721 0.528821" mass="0.34179" diaginertia="0.00351531 0.00348446 0.000541016" />
                    <joint name="right_wrist_roll_joint_X4" pos="0 0 0" axis="1 0 0" range="-1.57 1.57" armature="0.01" damping="0.5" />
                    <geom pos="-0.0219316 -0.0106854 -0.0421314" quat="0.701664 -0.0875555 -0.0875551 -0.701667" type="mesh" rgba="0.8 0.74902 0.913725 1" mesh="r_wrist" />
                    <geom size="0.028 0.0139" pos="-0.029 -0.0143421 -0.073183" quat="0.0566784 0.454214 -0.882246 0.110087" type="cylinder" />
                    <geom size="0.01955 0.0101 0.0287" pos="-0.0271408 -0.0178134 -0.0974748" quat="0.361255 0.281101 -0.701687 -0.545997" type="box" />
                    <geom size="0.01955 0.02 0.0407" pos="-0.0271408 -0.0252347 -0.126749" quat="0.361255 0.281101 -0.701687 -0.545997" type="box" />
                    <geom size="0.0161 0.02 0.0407" pos="-0.0289997 -0.0375645 -0.164785" quat="0.361255 0.281101 -0.701687 -0.545997" type="box" />
                    <geom size="0.00625 0.00555 0.00445" pos="-0.0532207 -0.0252657 -0.194622" quat="0.361255 0.281101 -0.701687 -0.545997" type="box" />
                    <geom size="0.00625 0.00555 0.00445" pos="-0.0376745 -0.0360217 -0.191896" quat="0.361255 0.281101 -0.701687 -0.545997" type="box" />
                    <geom size="0.00625 0.00555 0.00445" pos="-0.0223725 -0.0466087 -0.189212" quat="0.361255 0.281101 -0.701687 -0.545997" type="box" />
                    <geom size="0.00625 0.00555 0.00445" pos="-0.00674496 -0.057421 -0.186471" quat="0.361255 0.281101 -0.701687 -0.545997" type="box" />
                    <geom size="0.0075 0.006 0.007" pos="-0.00599054 -0.0207909 -0.121582" quat="-0.0377683 -0.302666 -0.945019 0.117924" type="box" />
                    <geom size="0.025 0.015 0.008" pos="0.0291137 -0.037775 -0.128367" quat="0.605412 -0.778043 0.102991 -0.13236" type="box" />
                    <geom size="0.0125 0.007 0.007" pos="0.0594459 -0.0536593 -0.148638" quat="0.605412 -0.778043 0.102991 -0.13236" type="box" />
                    <geom size="0.012 0.008 0.006" pos="0.0784888 -0.0640567 -0.161637" quat="0.605412 -0.778043 0.102991 -0.13236" type="box" />
                    <geom size="0.007 0.016 0.006" pos="-0.00796531 -0.0641243 -0.202031" quat="0.287361 -0.356296 0.533672 -0.711106" type="box" />
                    <geom size="0.007 0.021 0.005" pos="-0.00536697 -0.0721479 -0.239202" quat="0.287361 -0.356296 0.533672 -0.711106" type="box" />
                    <geom size="0.007 0.016 0.006" pos="-0.0240895 -0.0530591 -0.205217" quat="0.2811 -0.361256 0.545999 -0.701685" type="box" />
                    <geom size="0.007 0.023 0.005" pos="-0.022682 -0.060987 -0.244515" quat="0.2811 -0.361256 0.545999 -0.701685" type="box" />
                    <geom size="0.007 0.016 0.006" pos="-0.0403373 -0.0416891 -0.20756" quat="-0.271542 0.368494 -0.564189 0.687145" type="box" />
                    <geom size="0.007 0.021 0.005" pos="-0.0405511 -0.047991 -0.245153" quat="-0.271542 0.368494 -0.564189 0.687145" type="box" />
                    <geom size="0.007 0.016 0.006" pos="-0.0565396 -0.0300933 -0.20888" quat="-0.261815 0.375468 -0.581963 0.672158" type="box" />
                    <geom size="0.007 0.017 0.005" pos="-0.0586083 -0.0352869 -0.242489" quat="-0.261815 0.375468 -0.581963 0.672158" type="box" />
                  </body>
                </body>
              </body>
            </body>
          </body>
        </body>
        <site name="Default_site" pos="0 0 0" size="0.005" />
        <site name="PelvisIMU_site" pos="0.0705 0 -0.17" size="0.005" />
        <site name="TorsoIMU_site" pos="0.0665 0 0.35" size="0.005" />
      </body>
      <body name="urdf_hip_assembly" pos="0.0333787 0.076301 -0.467748">
        <inertial pos="-0.00420762 0.0689982 -6.23945e-06" quat="0.706157 0.707882 0.0110776 0.0110854" mass="1.73" diaginertia="0.00302373 0.00263533 0.00228673" />
        <joint name="left_hip_pitch_joint_X8" pos="0 0 0" axis="0 1 0" range="-2.53 1.57" armature="0.1" damping="0.5" />
        <geom pos="0.00253653 0.0520203 -3.27638e-05" quat="0.707105 0 0 -0.707108" type="mesh" rgba="0.0627451 0.266667 0.490196 1" mesh="hip" />
        <body name="urdf_l_upper_femur_assembly" pos="0.055 0.073 0">
          <inertial pos="-0.0457109 0.000405477 -0.147969" quat="0.812419 0.104926 0.172379 0.547038" mass="1.912" diaginertia="0.00558228 0.00552081 0.00296645" />
          <joint name="left_hip_roll_joint_X8" pos="0 0 0" axis="1 0 0" range="-0.35 3.14" armature="0.1" damping="0.5" />
          <geom pos="-0.0257799 0.00151581 -0.111785" quat="0.707105 0 0 -0.707108" type="mesh" rgba="0.141176 0.694118 0.65098 1" mesh="l_upper_femur" />
          <body name="urdf_lower_femur_assembly" pos="-0.053 -7.97086e-07 -0.217">
            <inertial pos="-1.0389e-08 -0.00357383 -0.103307" quat="0.70587 -0.0418434 0.0418548 0.705865" mass="1.817" diaginertia="0.00424172 0.00383469 0.00256196" />
            <joint name="left_hip_yaw_joint_X8" pos="0 0 0" axis="0 0 1" range="-1.57 1.57" armature="0.1" damping="0.5" />
            <geom pos="5.752e-09 0.00389134 -0.070766" quat="0.707105 0 0 -0.707108" type="mesh" rgba="0.380392 0.0470588 0.435294 1" mesh="lower_femur" />
            <body name="urdf_l_tibia_assembly" pos="0 0.055 -0.113">
              <inertial pos="0.00463897 -0.0449177 -0.190721" quat="0.996875 -0.0712688 -0.0114929 0.032074" mass="2.4" diaginertia="0.0786412 0.0774859 0.0140293" />
              <joint name="left_knee_joint_X8" pos="0 0 0" axis="0 1 0" range="-0.17 1.57" armature="0.1" damping="0.5" />
              <geom pos="0.000678037 -0.0431371 -0.186264" quat="0.707105 0 0 -0.707108" type="mesh" rgba="0.615686 0.811765 0.929412 1" mesh="urdf_l_tibia_assembly" />
              <body name="urdf_ankle_assembly" pos="-1.45092e-06 -0.051 -0.395">
                <inertial pos="-4.60715e-08 -0.004 -0.0125426" quat="0.707107 1.29867e-06 1.29867e-06 0.707107" mass="0.0818219" diaginertia="2.15245e-05 1.69449e-05 1.25404e-05" />
                <joint name="left_ankle_pitch_joint_X4" pos="0 0 0" axis="0 1 0" range="-0.79 0.79" armature="0.1" damping="0.3" />
                <geom pos="-4.60715e-08 -0.004 -0.0125426" quat="0.707105 0 0 -0.707108" type="mesh" rgba="0.615686 0.811765 0.929412 1" mesh="urdf_ankle_assembly" />
                <body name="urdf_foot_assembly" pos="-0.0120001 -0.004 -0.028">
                  <inertial pos="0.0427639 9.73e-10 -0.0209668" quat="0 0.706024 0 0.708188" mass="0.504" diaginertia="0.00229245 0.00202397 0.00036168" />
                  <joint name="left_ankle_roll_joint_X4" pos="0 0 0" axis="1 0 0" range="-0.79 0.79" armature="0.1" damping="0.3" />
                  <geom pos="0.0427639 0 -0.0209668" quat="0.707105 0 0 -0.707108" type="mesh" rgba="0.615686 0.811765 0.929412 1" mesh="urdf_foot_assembly" contype="0" conaffinity="0" />
                  <site name="LeftFoot_site" pos="0.043 0 -0.033" size="0.005" />
                  <geom name="LeftFootBox" type="box" size="0.115 0.045 0.005" pos="0.043 0 -0.033" friction="1.0 0.1 0.01" condim="4" contype="1" conaffinity="1" rgba="0.3 0.8 0.3 0.3" />
                </body>
              </body>
            </body>
          </body>
        </body>
      </body>
      <body name="urdf_hip_assembly_2" pos="0.0333787 -0.072699 -0.467748">
        <inertial pos="-0.00420762 -0.0739982 6.23945e-06" quat="0.706157 0.707882 -0.0110776 -0.0110854" mass="1.73" diaginertia="0.00302373 0.00263533 0.00228673" />
        <joint name="right_hip_pitch_joint_X8" pos="0 0 0" axis="0 1 0" range="-2.53 1.57" armature="0.1" damping="0.5" />
        <geom pos="0.00253653 -0.0570203 3.27638e-05" quat="9.38184e-07 -0.707105 -0.707108 9.38187e-07" type="mesh" rgba="0.0627451 0.266667 0.490196 1" mesh="hip" />
        <body name="urdf_r_upper_femur_assemby" pos="0.055 -0.078 0">
          <inertial pos="-0.0457092 -0.000405162 -0.147963" quat="0.546379 0.172424 0.104782 0.812872" mass="1.912" diaginertia="0.00558398 0.00552262 0.00296637" />
          <joint name="right_hip_roll_joint_X8" pos="0 0 0" axis="1 0 0" range="-3.14 0.35" armature="0.1" damping="0.5" />
          <geom pos="-0.0257733 -0.00151464 -0.111761" quat="0.707105 0 0 -0.707108" type="mesh" rgba="0.941176 0.87451 0.678431 1" mesh="r_upper_femur" />
          <body name="urdf_lower_femur_assembly_2" pos="-0.053 7.97086e-07 -0.217">
            <inertial pos="1.0389e-08 0.00357383 -0.103307" quat="0.70587 0.0418434 -0.0418548 0.705865" mass="1.817" diaginertia="0.00424172 0.00383469 0.00256196" />
            <joint name="right_hip_yaw_joint_X8" pos="0 0 0" axis="0 0 1" range="-1.57 1.57" armature="0.1" damping="0.5" />
            <geom pos="-5.752e-09 -0.00389134 -0.070766" quat="0.707105 0 0 0.707108" type="mesh" rgba="0.380392 0.0470588 0.435294 1" mesh="lower_femur" />
            <body name="urdf_r_tibia_assembly" pos="0 -0.055 -0.113">
              <inertial pos="0.00463902 0.0449175 -0.190727" quat="0.996881 0.0712617 -0.0115278 -0.0318828" mass="2.4" diaginertia="0.0786493 0.0774942 0.0140292" />
              <joint name="right_knee_joint_X8" pos="0 0 0" axis="0 1 0" range="-0.17 1.57" armature="0.1" damping="0.5" />
              <geom pos="0.000678616 0.0431372 -0.186264" quat="0.707105 0 0 -0.707108" type="mesh" rgba="0.615686 0.811765 0.929412 1" mesh="urdf_r_tibia_assembly" />
              <body name="urdf_ankle_assembly_2" pos="-4.02748e-07 0.059 -0.395">
                <inertial pos="-1.27886e-08 -0.004 -0.0125426" quat="0.707107 0 0 0.707107" mass="0.0818219" diaginertia="2.15245e-05 1.69449e-05 1.25404e-05" />
                <joint name="right_ankle_pitch_joint_X4" pos="0 0 0" axis="0 1 0" range="-0.79 0.79" armature="0.1" damping="0.3" />
                <geom pos="-1.27886e-08 -0.004 -0.0125426" quat="0.707105 0 0 -0.707108" type="mesh" rgba="0.615686 0.811765 0.929412 1" mesh="urdf_ankle_assembly" />
                <body name="urdf_foot_assembly_2" pos="-0.012 -0.004 -0.028">
                  <inertial pos="0.0427639 1.55004e-07 -0.0209668" quat="-2.62236e-06 0.706024 -2.61435e-06 0.708188" mass="0.504" diaginertia="0.00229245 0.00202397 0.00036168" />
                  <joint name="right_ankle_roll_joint_X4" pos="0 0 0" axis="1 0 0" range="-0.79 0.79" armature="0.1" damping="0.3" />
                  <geom pos="0.0427639 1.53975e-07 -0.0209668" quat="0.707105 0 0 -0.707108" type="mesh" rgba="0.615686 0.811765 0.929412 1" mesh="urdf_foot_assembly" contype="0" conaffinity="0" />
                  <site name="RightFoot_site" pos="0.043 0 -0.033" size="0.005" />
                  <geom name="RightFootBox" type="box" size="0.115 0.045 0.005" pos="0.043 0 -0.033" friction="1.0 0.1 0.01" condim="4" contype="1" conaffinity="1" rgba="0.3 0.8 0.3 0.3" />
                </body>
              </body>
            </body>
          </body>
        </body>
      </body>
    </body>
  </worldbody>
  <contact>
    <exclude body1="urdf_ankle_assembly" body2="urdf_ankle_assembly_2" />
    <exclude body1="urdf_ankle_assembly" body2="urdf_base" />
    <exclude body1="urdf_ankle_assembly" body2="urdf_foot_assembly" />
    <exclude body1="urdf_ankle_assembly" body2="urdf_foot_assembly_2" />
    <exclude body1="urdf_ankle_assembly" body2="urdf_hip_assembly" />
    <exclude body1="urdf_ankle_assembly" body2="urdf_hip_assembly_2" />
    <exclude body1="urdf_ankle_assembly" body2="urdf_l_elbow_assembly" />
    <exclude body1="urdf_ankle_assembly" body2="urdf_l_lower_forearm_assembly" />
    <exclude body1="urdf_ankle_assembly" body2="urdf_l_shoulder_assembly" />
    <exclude body1="urdf_ankle_assembly" body2="urdf_l_tibia_assembly" />
    <exclude body1="urdf_ankle_assembly" body2="urdf_l_upper_arm_assembly" />
    <exclude body1="urdf_ankle_assembly" body2="urdf_l_upper_femur_assembly" />
    <exclude body1="urdf_ankle_assembly" body2="urdf_l_upper_forearm_assembly" />
    <exclude body1="urdf_ankle_assembly" body2="urdf_l_wrist_assembly" />
    <exclude body1="urdf_ankle_assembly" body2="urdf_lower_femur_assembly" />
    <exclude body1="urdf_ankle_assembly" body2="urdf_lower_femur_assembly_2" />
    <exclude body1="urdf_ankle_assembly" body2="urdf_r_elbow_assembly" />
    <exclude body1="urdf_ankle_assembly" body2="urdf_r_lower_forearm_assembly" />
    <exclude body1="urdf_ankle_assembly" body2="urdf_r_shoulder_assembly" />
    <exclude body1="urdf_ankle_assembly" body2="urdf_r_tibia_assembly" />
    <exclude body1="urdf_ankle_assembly" body2="urdf_r_upper_arm_assembly" />
    <exclude body1="urdf_ankle_assembly" body2="urdf_r_upper_femur_assemby" />
    <exclude body1="urdf_ankle_assembly" body2="urdf_r_upper_forearm_assembly" />
    <exclude body1="urdf_ankle_assembly" body2="urdf_r_wrist_assembly" />
    <exclude body1="urdf_ankle_assembly" body2="urdf_simplified_torso" />
    <exclude body1="urdf_ankle_assembly_2" body2="urdf_base" />
    <exclude body1="urdf_ankle_assembly_2" body2="urdf_foot_assembly" />
    <exclude body1="urdf_ankle_assembly_2" body2="urdf_foot_assembly_2" />
    <exclude body1="urdf_ankle_assembly_2" body2="urdf_hip_assembly" />
    <exclude body1="urdf_ankle_assembly_2" body2="urdf_hip_assembly_2" />
    <exclude body1="urdf_ankle_assembly_2" body2="urdf_l_elbow_assembly" />
    <exclude body1="urdf_ankle_assembly_2" body2="urdf_l_lower_forearm_assembly" />
    <exclude body1="urdf_ankle_assembly_2" body2="urdf_l_shoulder_assembly" />
    <exclude body1="urdf_ankle_assembly_2" body2="urdf_l_tibia_assembly" />
    <exclude body1="urdf_ankle_assembly_2" body2="urdf_l_upper_arm_assembly" />
    <exclude body1="urdf_ankle_assembly_2" body2="urdf_l_upper_femur_assembly" />
    <exclude body1="urdf_ankle_assembly_2" body2="urdf_l_upper_forearm_assembly" />
    <exclude body1="urdf_ankle_assembly_2" body2="urdf_l_wrist_assembly" />
    <exclude body1="urdf_ankle_assembly_2" body2="urdf_lower_femur_assembly" />
    <exclude body1="urdf_ankle_assembly_2" body2="urdf_lower_femur_assembly_2" />
    <exclude body1="urdf_ankle_assembly_2" body2="urdf_r_elbow_assembly" />
    <exclude body1="urdf_ankle_assembly_2" body2="urdf_r_lower_forearm_assembly" />
    <exclude body1="urdf_ankle_assembly_2" body2="urdf_r_shoulder_assembly" />
    <exclude body1="urdf_ankle_assembly_2" body2="urdf_r_tibia_assembly" />
    <exclude body1="urdf_ankle_assembly_2" body2="urdf_r_upper_arm_assembly" />
    <exclude body1="urdf_ankle_assembly_2" body2="urdf_r_upper_femur_assemby" />
    <exclude body1="urdf_ankle_assembly_2" body2="urdf_r_upper_forearm_assembly" />
    <exclude body1="urdf_ankle_assembly_2" body2="urdf_r_wrist_assembly" />
    <exclude body1="urdf_ankle_assembly_2" body2="urdf_simplified_torso" />
    <exclude body1="urdf_base" body2="urdf_foot_assembly" />
    <exclude body1="urdf_base" body2="urdf_foot_assembly_2" />
    <exclude body1="urdf_base" body2="urdf_hip_assembly" />
    <exclude body1="urdf_base" body2="urdf_hip_assembly_2" />
    <exclude body1="urdf_base" body2="urdf_l_elbow_assembly" />
    <exclude body1="urdf_base" body2="urdf_l_lower_forearm_assembly" />
    <exclude body1="urdf_base" body2="urdf_l_shoulder_assembly" />
    <exclude body1="urdf_base" body2="urdf_l_tibia_assembly" />
    <exclude body1="urdf_base" body2="urdf_l_upper_arm_assembly" />
    <exclude body1="urdf_base" body2="urdf_l_upper_femur_assembly" />
    <exclude body1="urdf_base" body2="urdf_l_upper_forearm_assembly" />
    <exclude body1="urdf_base" body2="urdf_l_wrist_assembly" />
    <exclude body1="urdf_base" body2="urdf_lower_femur_assembly" />
    <exclude body1="urdf_base" body2="urdf_lower_femur_assembly_2" />
    <exclude body1="urdf_base" body2="urdf_r_elbow_assembly" />
    <exclude body1="urdf_base" body2="urdf_r_lower_forearm_assembly" />
    <exclude body1="urdf_base" body2="urdf_r_shoulder_assembly" />
    <exclude body1="urdf_base" body2="urdf_r_tibia_assembly" />
    <exclude body1="urdf_base" body2="urdf_r_upper_arm_assembly" />
    <exclude body1="urdf_base" body2="urdf_r_upper_femur_assemby" />
    <exclude body1="urdf_base" body2="urdf_r_upper_forearm_assembly" />
    <exclude body1="urdf_base" body2="urdf_r_wrist_assembly" />
    <exclude body1="urdf_base" body2="urdf_simplified_torso" />
    <exclude body1="urdf_foot_assembly" body2="urdf_foot_assembly_2" />
    <exclude body1="urdf_foot_assembly" body2="urdf_hip_assembly" />
    <exclude body1="urdf_foot_assembly" body2="urdf_hip_assembly_2" />
    <exclude body1="urdf_foot_assembly" body2="urdf_l_elbow_assembly" />
    <exclude body1="urdf_foot_assembly" body2="urdf_l_lower_forearm_assembly" />
    <exclude body1="urdf_foot_assembly" body2="urdf_l_shoulder_assembly" />
    <exclude body1="urdf_foot_assembly" body2="urdf_l_tibia_assembly" />
    <exclude body1="urdf_foot_assembly" body2="urdf_l_upper_arm_assembly" />
    <exclude body1="urdf_foot_assembly" body2="urdf_l_upper_femur_assembly" />
    <exclude body1="urdf_foot_assembly" body2="urdf_l_upper_forearm_assembly" />
    <exclude body1="urdf_foot_assembly" body2="urdf_l_wrist_assembly" />
    <exclude body1="urdf_foot_assembly" body2="urdf_lower_femur_assembly" />
    <exclude body1="urdf_foot_assembly" body2="urdf_lower_femur_assembly_2" />
    <exclude body1="urdf_foot_assembly" body2="urdf_r_elbow_assembly" />
    <exclude body1="urdf_foot_assembly" body2="urdf_r_lower_forearm_assembly" />
    <exclude body1="urdf_foot_assembly" body2="urdf_r_shoulder_assembly" />
    <exclude body1="urdf_foot_assembly" body2="urdf_r_tibia_assembly" />
    <exclude body1="urdf_foot_assembly" body2="urdf_r_upper_arm_assembly" />
    <exclude body1="urdf_foot_assembly" body2="urdf_r_upper_femur_assemby" />
    <exclude body1="urdf_foot_assembly" body2="urdf_r_upper_forearm_assembly" />
    <exclude body1="urdf_foot_assembly" body2="urdf_r_wrist_assembly" />
    <exclude body1="urdf_foot_assembly" body2="urdf_simplified_torso" />
    <exclude body1="urdf_foot_assembly_2" body2="urdf_hip_assembly" />
    <exclude body1="urdf_foot_assembly_2" body2="urdf_hip_assembly_2" />
    <exclude body1="urdf_foot_assembly_2" body2="urdf_l_elbow_assembly" />
    <exclude body1="urdf_foot_assembly_2" body2="urdf_l_lower_forearm_assembly" />
    <exclude body1="urdf_foot_assembly_2" body2="urdf_l_shoulder_assembly" />
    <exclude body1="urdf_foot_assembly_2" body2="urdf_l_tibia_assembly" />
    <exclude body1="urdf_foot_assembly_2" body2="urdf_l_upper_arm_assembly" />
    <exclude body1="urdf_foot_assembly_2" body2="urdf_l_upper_femur_assembly" />
    <exclude body1="urdf_foot_assembly_2" body2="urdf_l_upper_forearm_assembly" />
    <exclude body1="urdf_foot_assembly_2" body2="urdf_l_wrist_assembly" />
    <exclude body1="urdf_foot_assembly_2" body2="urdf_lower_femur_assembly" />
    <exclude body1="urdf_foot_assembly_2" body2="urdf_lower_femur_assembly_2" />
    <exclude body1="urdf_foot_assembly_2" body2="urdf_r_elbow_assembly" />
    <exclude body1="urdf_foot_assembly_2" body2="urdf_r_lower_forearm_assembly" />
    <exclude body1="urdf_foot_assembly_2" body2="urdf_r_shoulder_assembly" />
    <exclude body1="urdf_foot_assembly_2" body2="urdf_r_tibia_assembly" />
    <exclude body1="urdf_foot_assembly_2" body2="urdf_r_upper_arm_assembly" />
    <exclude body1="urdf_foot_assembly_2" body2="urdf_r_upper_femur_assemby" />
    <exclude body1="urdf_foot_assembly_2" body2="urdf_r_upper_forearm_assembly" />
    <exclude body1="urdf_foot_assembly_2" body2="urdf_r_wrist_assembly" />
    <exclude body1="urdf_foot_assembly_2" body2="urdf_simplified_torso" />
    <exclude body1="urdf_hip_assembly" body2="urdf_hip_assembly_2" />
    <exclude body1="urdf_hip_assembly" body2="urdf_l_elbow_assembly" />
    <exclude body1="urdf_hip_assembly" body2="urdf_l_lower_forearm_assembly" />
    <exclude body1="urdf_hip_assembly" body2="urdf_l_shoulder_assembly" />
    <exclude body1="urdf_hip_assembly" body2="urdf_l_tibia_assembly" />
    <exclude body1="urdf_hip_assembly" body2="urdf_l_upper_arm_assembly" />
    <exclude body1="urdf_hip_assembly" body2="urdf_l_upper_femur_assembly" />
    <exclude body1="urdf_hip_assembly" body2="urdf_l_upper_forearm_assembly" />
    <exclude body1="urdf_hip_assembly" body2="urdf_l_wrist_assembly" />
    <exclude body1="urdf_hip_assembly" body2="urdf_lower_femur_assembly" />
    <exclude body1="urdf_hip_assembly" body2="urdf_lower_femur_assembly_2" />
    <exclude body1="urdf_hip_assembly" body2="urdf_r_elbow_assembly" />
    <exclude body1="urdf_hip_assembly" body2="urdf_r_lower_forearm_assembly" />
    <exclude body1="urdf_hip_assembly" body2="urdf_r_shoulder_assembly" />
    <exclude body1="urdf_hip_assembly" body2="urdf_r_tibia_assembly" />
    <exclude body1="urdf_hip_assembly" body2="urdf_r_upper_arm_assembly" />
    <exclude body1="urdf_hip_assembly" body2="urdf_r_upper_femur_assemby" />
    <exclude body1="urdf_hip_assembly" body2="urdf_r_upper_forearm_assembly" />
    <exclude body1="urdf_hip_assembly" body2="urdf_r_wrist_assembly" />
    <exclude body1="urdf_hip_assembly" body2="urdf_simplified_torso" />
    <exclude body1="urdf_hip_assembly_2" body2="urdf_l_elbow_assembly" />
    <exclude body1="urdf_hip_assembly_2" body2="urdf_l_lower_forearm_assembly" />
    <exclude body1="urdf_hip_assembly_2" body2="urdf_l_shoulder_assembly" />
    <exclude body1="urdf_hip_assembly_2" body2="urdf_l_tibia_assembly" />
    <exclude body1="urdf_hip_assembly_2" body2="urdf_l_upper_arm_assembly" />
    <exclude body1="urdf_hip_assembly_2" body2="urdf_l_upper_femur_assembly" />
    <exclude body1="urdf_hip_assembly_2" body2="urdf_l_upper_forearm_assembly" />
    <exclude body1="urdf_hip_assembly_2" body2="urdf_l_wrist_assembly" />
    <exclude body1="urdf_hip_assembly_2" body2="urdf_lower_femur_assembly" />
    <exclude body1="urdf_hip_assembly_2" body2="urdf_lower_femur_assembly_2" />
    <exclude body1="urdf_hip_assembly_2" body2="urdf_r_elbow_assembly" />
    <exclude body1="urdf_hip_assembly_2" body2="urdf_r_lower_forearm_assembly" />
    <exclude body1="urdf_hip_assembly_2" body2="urdf_r_shoulder_assembly" />
    <exclude body1="urdf_hip_assembly_2" body2="urdf_r_tibia_assembly" />
    <exclude body1="urdf_hip_assembly_2" body2="urdf_r_upper_arm_assembly" />
    <exclude body1="urdf_hip_assembly_2" body2="urdf_r_upper_femur_assemby" />
    <exclude body1="urdf_hip_assembly_2" body2="urdf_r_upper_forearm_assembly" />
    <exclude body1="urdf_hip_assembly_2" body2="urdf_r_wrist_assembly" />
    <exclude body1="urdf_hip_assembly_2" body2="urdf_simplified_torso" />
    <exclude body1="urdf_l_elbow_assembly" body2="urdf_l_lower_forearm_assembly" />
    <exclude body1="urdf_l_elbow_assembly" body2="urdf_l_shoulder_assembly" />
    <exclude body1="urdf_l_elbow_assembly" body2="urdf_l_tibia_assembly" />
    <exclude body1="urdf_l_elbow_assembly" body2="urdf_l_upper_arm_assembly" />
    <exclude body1="urdf_l_elbow_assembly" body2="urdf_l_upper_femur_assembly" />
    <exclude body1="urdf_l_elbow_assembly" body2="urdf_l_upper_forearm_assembly" />
    <exclude body1="urdf_l_elbow_assembly" body2="urdf_l_wrist_assembly" />
    <exclude body1="urdf_l_elbow_assembly" body2="urdf_lower_femur_assembly" />
    <exclude body1="urdf_l_elbow_assembly" body2="urdf_lower_femur_assembly_2" />
    <exclude body1="urdf_l_elbow_assembly" body2="urdf_r_elbow_assembly" />
    <exclude body1="urdf_l_elbow_assembly" body2="urdf_r_lower_forearm_assembly" />
    <exclude body1="urdf_l_elbow_assembly" body2="urdf_r_shoulder_assembly" />
    <exclude body1="urdf_l_elbow_assembly" body2="urdf_r_tibia_assembly" />
    <exclude body1="urdf_l_elbow_assembly" body2="urdf_r_upper_arm_assembly" />
    <exclude body1="urdf_l_elbow_assembly" body2="urdf_r_upper_femur_assemby" />
    <exclude body1="urdf_l_elbow_assembly" body2="urdf_r_upper_forearm_assembly" />
    <exclude body1="urdf_l_elbow_assembly" body2="urdf_r_wrist_assembly" />
    <exclude body1="urdf_l_elbow_assembly" body2="urdf_simplified_torso" />
    <exclude body1="urdf_l_lower_forearm_assembly" body2="urdf_l_shoulder_assembly" />
    <exclude body1="urdf_l_lower_forearm_assembly" body2="urdf_l_tibia_assembly" />
    <exclude body1="urdf_l_lower_forearm_assembly" body2="urdf_l_upper_arm_assembly" />
    <exclude body1="urdf_l_lower_forearm_assembly" body2="urdf_l_upper_femur_assembly" />
    <exclude body1="urdf_l_lower_forearm_assembly" body2="urdf_l_upper_forearm_assembly" />
    <exclude body1="urdf_l_lower_forearm_assembly" body2="urdf_l_wrist_assembly" />
    <exclude body1="urdf_l_lower_forearm_assembly" body2="urdf_lower_femur_assembly" />
    <exclude body1="urdf_l_lower_forearm_assembly" body2="urdf_lower_femur_assembly_2" />
    <exclude body1="urdf_l_lower_forearm_assembly" body2="urdf_r_elbow_assembly" />
    <exclude body1="urdf_l_lower_forearm_assembly" body2="urdf_r_lower_forearm_assembly" />
    <exclude body1="urdf_l_lower_forearm_assembly" body2="urdf_r_shoulder_assembly" />
    <exclude body1="urdf_l_lower_forearm_assembly" body2="urdf_r_tibia_assembly" />
    <exclude body1="urdf_l_lower_forearm_assembly" body2="urdf_r_upper_arm_assembly" />
    <exclude body1="urdf_l_lower_forearm_assembly" body2="urdf_r_upper_femur_assemby" />
    <exclude body1="urdf_l_lower_forearm_assembly" body2="urdf_r_upper_forearm_assembly" />
    <exclude body1="urdf_l_lower_forearm_assembly" body2="urdf_r_wrist_assembly" />
    <exclude body1="urdf_l_lower_forearm_assembly" body2="urdf_simplified_torso" />
    <exclude body1="urdf_l_shoulder_assembly" body2="urdf_l_tibia_assembly" />
    <exclude body1="urdf_l_shoulder_assembly" body2="urdf_l_upper_arm_assembly" />
    <exclude body1="urdf_l_shoulder_assembly" body2="urdf_l_upper_femur_assembly" />
    <exclude body1="urdf_l_shoulder_assembly" body2="urdf_l_upper_forearm_assembly" />
    <exclude body1="urdf_l_shoulder_assembly" body2="urdf_l_wrist_assembly" />
    <exclude body1="urdf_l_shoulder_assembly" body2="urdf_lower_femur_assembly" />
    <exclude body1="urdf_l_shoulder_assembly" body2="urdf_lower_femur_assembly_2" />
    <exclude body1="urdf_l_shoulder_assembly" body2="urdf_r_elbow_assembly" />
    <exclude body1="urdf_l_shoulder_assembly" body2="urdf_r_lower_forearm_assembly" />
    <exclude body1="urdf_l_shoulder_assembly" body2="urdf_r_shoulder_assembly" />
    <exclude body1="urdf_l_shoulder_assembly" body2="urdf_r_tibia_assembly" />
    <exclude body1="urdf_l_shoulder_assembly" body2="urdf_r_upper_arm_assembly" />
    <exclude body1="urdf_l_shoulder_assembly" body2="urdf_r_upper_femur_assemby" />
    <exclude body1="urdf_l_shoulder_assembly" body2="urdf_r_upper_forearm_assembly" />
    <exclude body1="urdf_l_shoulder_assembly" body2="urdf_r_wrist_assembly" />
    <exclude body1="urdf_l_shoulder_assembly" body2="urdf_simplified_torso" />
    <exclude body1="urdf_l_tibia_assembly" body2="urdf_l_upper_arm_assembly" />
    <exclude body1="urdf_l_tibia_assembly" body2="urdf_l_upper_femur_assembly" />
    <exclude body1="urdf_l_tibia_assembly" body2="urdf_l_upper_forearm_assembly" />
    <exclude body1="urdf_l_tibia_assembly" body2="urdf_l_wrist_assembly" />
    <exclude body1="urdf_l_tibia_assembly" body2="urdf_lower_femur_assembly" />
    <exclude body1="urdf_l_tibia_assembly" body2="urdf_lower_femur_assembly_2" />
    <exclude body1="urdf_l_tibia_assembly" body2="urdf_r_elbow_assembly" />
    <exclude body1="urdf_l_tibia_assembly" body2="urdf_r_lower_forearm_assembly" />
    <exclude body1="urdf_l_tibia_assembly" body2="urdf_r_shoulder_assembly" />
    <exclude body1="urdf_l_tibia_assembly" body2="urdf_r_tibia_assembly" />
    <exclude body1="urdf_l_tibia_assembly" body2="urdf_r_upper_arm_assembly" />
    <exclude body1="urdf_l_tibia_assembly" body2="urdf_r_upper_femur_assemby" />
    <exclude body1="urdf_l_tibia_assembly" body2="urdf_r_upper_forearm_assembly" />
    <exclude body1="urdf_l_tibia_assembly" body2="urdf_r_wrist_assembly" />
    <exclude body1="urdf_l_tibia_assembly" body2="urdf_simplified_torso" />
    <exclude body1="urdf_l_upper_arm_assembly" body2="urdf_l_upper_femur_assembly" />
    <exclude body1="urdf_l_upper_arm_assembly" body2="urdf_l_upper_forearm_assembly" />
    <exclude body1="urdf_l_upper_arm_assembly" body2="urdf_l_wrist_assembly" />
    <exclude body1="urdf_l_upper_arm_assembly" body2="urdf_lower_femur_assembly" />
    <exclude body1="urdf_l_upper_arm_assembly" body2="urdf_lower_femur_assembly_2" />
    <exclude body1="urdf_l_upper_arm_assembly" body2="urdf_r_elbow_assembly" />
    <exclude body1="urdf_l_upper_arm_assembly" body2="urdf_r_lower_forearm_assembly" />
    <exclude body1="urdf_l_upper_arm_assembly" body2="urdf_r_shoulder_assembly" />
    <exclude body1="urdf_l_upper_arm_assembly" body2="urdf_r_tibia_assembly" />
    <exclude body1="urdf_l_upper_arm_assembly" body2="urdf_r_upper_arm_assembly" />
    <exclude body1="urdf_l_upper_arm_assembly" body2="urdf_r_upper_femur_assemby" />
    <exclude body1="urdf_l_upper_arm_assembly" body2="urdf_r_upper_forearm_assembly" />
    <exclude body1="urdf_l_upper_arm_assembly" body2="urdf_r_wrist_assembly" />
    <exclude body1="urdf_l_upper_arm_assembly" body2="urdf_simplified_torso" />
    <exclude body1="urdf_l_upper_femur_assembly" body2="urdf_l_upper_forearm_assembly" />
    <exclude body1="urdf_l_upper_femur_assembly" body2="urdf_l_wrist_assembly" />
    <exclude body1="urdf_l_upper_femur_assembly" body2="urdf_lower_femur_assembly" />
    <exclude body1="urdf_l_upper_femur_assembly" body2="urdf_lower_femur_assembly_2" />
    <exclude body1="urdf_l_upper_femur_assembly" body2="urdf_r_elbow_assembly" />
    <exclude body1="urdf_l_upper_femur_assembly" body2="urdf_r_lower_forearm_assembly" />
    <exclude body1="urdf_l_upper_femur_assembly" body2="urdf_r_shoulder_assembly" />
    <exclude body1="urdf_l_upper_femur_assembly" body2="urdf_r_tibia_assembly" />
    <exclude body1="urdf_l_upper_femur_assembly" body2="urdf_r_upper_arm_assembly" />
    <exclude body1="urdf_l_upper_femur_assembly" body2="urdf_r_upper_femur_assemby" />
    <exclude body1="urdf_l_upper_femur_assembly" body2="urdf_r_upper_forearm_assembly" />
    <exclude body1="urdf_l_upper_femur_assembly" body2="urdf_r_wrist_assembly" />
    <exclude body1="urdf_l_upper_femur_assembly" body2="urdf_simplified_torso" />
    <exclude body1="urdf_l_upper_forearm_assembly" body2="urdf_l_wrist_assembly" />
    <exclude body1="urdf_l_upper_forearm_assembly" body2="urdf_lower_femur_assembly" />
    <exclude body1="urdf_l_upper_forearm_assembly" body2="urdf_lower_femur_assembly_2" />
    <exclude body1="urdf_l_upper_forearm_assembly" body2="urdf_r_elbow_assembly" />
    <exclude body1="urdf_l_upper_forearm_assembly" body2="urdf_r_lower_forearm_assembly" />
    <exclude body1="urdf_l_upper_forearm_assembly" body2="urdf_r_shoulder_assembly" />
    <exclude body1="urdf_l_upper_forearm_assembly" body2="urdf_r_tibia_assembly" />
    <exclude body1="urdf_l_upper_forearm_assembly" body2="urdf_r_upper_arm_assembly" />
    <exclude body1="urdf_l_upper_forearm_assembly" body2="urdf_r_upper_femur_assemby" />
    <exclude body1="urdf_l_upper_forearm_assembly" body2="urdf_r_upper_forearm_assembly" />
    <exclude body1="urdf_l_upper_forearm_assembly" body2="urdf_r_wrist_assembly" />
    <exclude body1="urdf_l_upper_forearm_assembly" body2="urdf_simplified_torso" />
    <exclude body1="urdf_l_wrist_assembly" body2="urdf_lower_femur_assembly" />
    <exclude body1="urdf_l_wrist_assembly" body2="urdf_lower_femur_assembly_2" />
    <exclude body1="urdf_l_wrist_assembly" body2="urdf_r_elbow_assembly" />
    <exclude body1="urdf_l_wrist_assembly" body2="urdf_r_lower_forearm_assembly" />
    <exclude body1="urdf_l_wrist_assembly" body2="urdf_r_shoulder_assembly" />
    <exclude body1="urdf_l_wrist_assembly" body2="urdf_r_tibia_assembly" />
    <exclude body1="urdf_l_wrist_assembly" body2="urdf_r_upper_arm_assembly" />
    <exclude body1="urdf_l_wrist_assembly" body2="urdf_r_upper_femur_assemby" />
    <exclude body1="urdf_l_wrist_assembly" body2="urdf_r_upper_forearm_assembly" />
    <exclude body1="urdf_l_wrist_assembly" body2="urdf_r_wrist_assembly" />
    <exclude body1="urdf_l_wrist_assembly" body2="urdf_simplified_torso" />
    <exclude body1="urdf_lower_femur_assembly" body2="urdf_lower_femur_assembly_2" />
    <exclude body1="urdf_lower_femur_assembly" body2="urdf_r_elbow_assembly" />
    <exclude body1="urdf_lower_femur_assembly" body2="urdf_r_lower_forearm_assembly" />
    <exclude body1="urdf_lower_femur_assembly" body2="urdf_r_shoulder_assembly" />
    <exclude body1="urdf_lower_femur_assembly" body2="urdf_r_tibia_assembly" />
    <exclude body1="urdf_lower_femur_assembly" body2="urdf_r_upper_arm_assembly" />
    <exclude body1="urdf_lower_femur_assembly" body2="urdf_r_upper_femur_assemby" />
    <exclude body1="urdf_lower_femur_assembly" body2="urdf_r_upper_forearm_assembly" />
    <exclude body1="urdf_lower_femur_assembly" body2="urdf_r_wrist_assembly" />
    <exclude body1="urdf_lower_femur_assembly" body2="urdf_simplified_torso" />
    <exclude body1="urdf_lower_femur_assembly_2" body2="urdf_r_elbow_assembly" />
    <exclude body1="urdf_lower_femur_assembly_2" body2="urdf_r_lower_forearm_assembly" />
    <exclude body1="urdf_lower_femur_assembly_2" body2="urdf_r_shoulder_assembly" />
    <exclude body1="urdf_lower_femur_assembly_2" body2="urdf_r_tibia_assembly" />
    <exclude body1="urdf_lower_femur_assembly_2" body2="urdf_r_upper_arm_assembly" />
    <exclude body1="urdf_lower_femur_assembly_2" body2="urdf_r_upper_femur_assemby" />
    <exclude body1="urdf_lower_femur_assembly_2" body2="urdf_r_upper_forearm_assembly" />
    <exclude body1="urdf_lower_femur_assembly_2" body2="urdf_r_wrist_assembly" />
    <exclude body1="urdf_lower_femur_assembly_2" body2="urdf_simplified_torso" />
    <exclude body1="urdf_r_elbow_assembly" body2="urdf_r_lower_forearm_assembly" />
    <exclude body1="urdf_r_elbow_assembly" body2="urdf_r_shoulder_assembly" />
    <exclude body1="urdf_r_elbow_assembly" body2="urdf_r_tibia_assembly" />
    <exclude body1="urdf_r_elbow_assembly" body2="urdf_r_upper_arm_assembly" />
    <exclude body1="urdf_r_elbow_assembly" body2="urdf_r_upper_femur_assemby" />
    <exclude body1="urdf_r_elbow_assembly" body2="urdf_r_upper_forearm_assembly" />
    <exclude body1="urdf_r_elbow_assembly" body2="urdf_r_wrist_assembly" />
    <exclude body1="urdf_r_elbow_assembly" body2="urdf_simplified_torso" />
    <exclude body1="urdf_r_lower_forearm_assembly" body2="urdf_r_shoulder_assembly" />
    <exclude body1="urdf_r_lower_forearm_assembly" body2="urdf_r_tibia_assembly" />
    <exclude body1="urdf_r_lower_forearm_assembly" body2="urdf_r_upper_arm_assembly" />
    <exclude body1="urdf_r_lower_forearm_assembly" body2="urdf_r_upper_femur_assemby" />
    <exclude body1="urdf_r_lower_forearm_assembly" body2="urdf_r_upper_forearm_assembly" />
    <exclude body1="urdf_r_lower_forearm_assembly" body2="urdf_r_wrist_assembly" />
    <exclude body1="urdf_r_lower_forearm_assembly" body2="urdf_simplified_torso" />
    <exclude body1="urdf_r_shoulder_assembly" body2="urdf_r_tibia_assembly" />
    <exclude body1="urdf_r_shoulder_assembly" body2="urdf_r_upper_arm_assembly" />
    <exclude body1="urdf_r_shoulder_assembly" body2="urdf_r_upper_femur_assemby" />
    <exclude body1="urdf_r_shoulder_assembly" body2="urdf_r_upper_forearm_assembly" />
    <exclude body1="urdf_r_shoulder_assembly" body2="urdf_r_wrist_assembly" />
    <exclude body1="urdf_r_shoulder_assembly" body2="urdf_simplified_torso" />
    <exclude body1="urdf_r_tibia_assembly" body2="urdf_r_upper_arm_assembly" />
    <exclude body1="urdf_r_tibia_assembly" body2="urdf_r_upper_femur_assemby" />
    <exclude body1="urdf_r_tibia_assembly" body2="urdf_r_upper_forearm_assembly" />
    <exclude body1="urdf_r_tibia_assembly" body2="urdf_r_wrist_assembly" />
    <exclude body1="urdf_r_tibia_assembly" body2="urdf_simplified_torso" />
    <exclude body1="urdf_r_upper_arm_assembly" body2="urdf_r_upper_femur_assemby" />
    <exclude body1="urdf_r_upper_arm_assembly" body2="urdf_r_upper_forearm_assembly" />
    <exclude body1="urdf_r_upper_arm_assembly" body2="urdf_r_wrist_assembly" />
    <exclude body1="urdf_r_upper_arm_assembly" body2="urdf_simplified_torso" />
    <exclude body1="urdf_r_upper_femur_assemby" body2="urdf_r_upper_forearm_assembly" />
    <exclude body1="urdf_r_upper_femur_assemby" body2="urdf_r_wrist_assembly" />
    <exclude body1="urdf_r_upper_femur_assemby" body2="urdf_simplified_torso" />
    <exclude body1="urdf_r_upper_forearm_assembly" body2="urdf_r_wrist_assembly" />
    <exclude body1="urdf_r_upper_forearm_assembly" body2="urdf_simplified_torso" />
    <exclude body1="urdf_r_wrist_assembly" body2="urdf_simplified_torso" />
  </contact>
  <option timestep="0.001" impratio="10" solver="Newton" iterations="50" tolerance="1e-10" noslip_iterations="10" />
  <default>
    <geom friction="1.3 0.005 0.0001" condim="4" />
  </default>
  <actuator>
    <motor name="waist_yaw_joint_X8" joint="waist_yaw_joint_X8" />
    <motor name="left_shoulder_pitch_joint_X6" joint="left_shoulder_pitch_joint_X6" />
    <motor name="left_shoulder_roll_joint_X6" joint="left_shoulder_roll_joint_X6" />
    <motor name="left_shoulder_yaw_joint_X4" joint="left_shoulder_yaw_joint_X4" />
    <motor name="left_elbow_pitch_joint_X6" joint="left_elbow_pitch_joint_X6" />
    <motor name="left_wrist_yaw_joint_X4" joint="left_wrist_yaw_joint_X4" />
    <motor name="left_wrist_roll_joint_X4" joint="left_wrist_roll_joint_X4" />
    <motor name="right_shoulder_pitch_joint_X6" joint="right_shoulder_pitch_joint_X6" />
    <motor name="right_shoulder_roll_joint_X6" joint="right_shoulder_roll_joint_X6" />
    <motor name="right_shoulder_yaw_joint_X4" joint="right_shoulder_yaw_joint_X4" />
    <motor name="right_elbow_pitch_joint_X6" joint="right_elbow_pitch_joint_X6" />
    <motor name="right_wrist_yaw_joint_X4" joint="right_wrist_yaw_joint_X4" />
    <motor name="right_wrist_roll_joint_X4" joint="right_wrist_roll_joint_X4" />
    <motor name="left_hip_pitch_joint_X8" joint="left_hip_pitch_joint_X8" />
    <motor name="left_hip_roll_joint_X8" joint="left_hip_roll_joint_X8" />
    <motor name="left_hip_yaw_joint_X8" joint="left_hip_yaw_joint_X8" />
    <motor name="left_knee_joint_X8" joint="left_knee_joint_X8" />
    <motor name="left_ankle_pitch_joint_X4" joint="left_ankle_pitch_joint_X4" />
    <motor name="left_ankle_roll_joint_X4" joint="left_ankle_roll_joint_X4" />
    <motor name="right_hip_pitch_joint_X8" joint="right_hip_pitch_joint_X8" />
    <motor name="right_hip_roll_joint_X8" joint="right_hip_roll_joint_X8" />
    <motor name="right_hip_yaw_joint_X8" joint="right_hip_yaw_joint_X8" />
    <motor name="right_knee_joint_X8" joint="right_knee_joint_X8" />
    <motor name="right_ankle_pitch_joint_X4" joint="right_ankle_pitch_joint_X4" />
    <motor name="right_ankle_roll_joint_X4" joint="right_ankle_roll_joint_X4" />
  </actuator>
  <sensor>
    <force name="LeftFoot_fsensor" site="LeftFoot_site" />
    <torque name="LeftFoot_tsensor" site="LeftFoot_site" />
    <force name="RightFoot_fsensor" site="RightFoot_site" />
    <torque name="RightFoot_tsensor" site="RightFoot_site" />
    <gyro name="Default_gyro" site="Default_site" />
    <accelerometer name="Default_accelerometer" site="Default_site" />
    <gyro name="PelvisIMU_gyro" site="PelvisIMU_site" />
    <accelerometer name="PelvisIMU_accelerometer" site="PelvisIMU_site" />
    <gyro name="TorsoIMU_gyro" site="TorsoIMU_site" />
    <accelerometer name="TorsoIMU_accelerometer" site="TorsoIMU_site" />
  </sensor>
  <keyframe>
    <key name="home" qpos="0.0 0.0 1.25 1.0 0.0 0.0 0.0 0.0 0.0 0.0 0.0 0.0 0.0 0.0 0.0 0.0 0.0 0.0 0.0 0.0 -0.15 0.0 0.0 0.3 -0.15 0.0 -0.15 0.0 0.0 0.3 -0.15 0.0" />
  </keyframe>
</mujoco>