<?xml version='1.0' encoding='utf-8'?>
<mujoco model="robot_harambe_v04">
  <compiler angle="radian" />
  <asset>
    <mesh name="b_base" content_type="model/stl" file="/home/alex/Documents/GitHub/ldr-harambe-arms-sim2real/src/robot_description/full_robot_description/meshes/visual/b_base.stl" />
    <mesh name="plate_base_right" content_type="model/stl" file="/home/alex/Documents/GitHub/ldr-harambe-arms-sim2real/src/robot_description/full_robot_description/meshes/visual/plate_base_right.stl" />
    <mesh name="f_base" content_type="model/stl" file="/home/alex/Documents/GitHub/ldr-harambe-arms-sim2real/src/robot_description/full_robot_description/meshes/visual/f_base.stl" />
    <mesh name="plate_base_left" content_type="model/stl" file="/home/alex/Documents/GitHub/ldr-harambe-arms-sim2real/src/robot_description/full_robot_description/meshes/visual/plate_base_left.stl" />
    <mesh name="plate_base_top" content_type="model/stl" file="/home/alex/Documents/GitHub/ldr-harambe-arms-sim2real/src/robot_description/full_robot_description/meshes/visual/plate_base_top.stl" />
    <mesh name="jockstrap" content_type="model/stl" file="/home/alex/Documents/GitHub/ldr-harambe-arms-sim2real/src/robot_description/full_robot_description/meshes/visual/jockstrap.stl" />
    <mesh name="urdf_simplified_torso" content_type="model/stl" file="/home/alex/Documents/GitHub/ldr-harambe-arms-sim2real/src/robot_description/full_robot_description/meshes/visual/urdf_simplified_torso.stl" />
    <mesh name="head" content_type="model/stl" file="/home/alex/Documents/GitHub/ldr-harambe-arms-sim2real/src/robot_description/full_robot_description/meshes/visual/head.stl" />
    <mesh name="l_shoulder" content_type="model/stl" file="/home/alex/Documents/GitHub/ldr-harambe-arms-sim2real/src/robot_description/full_robot_description/meshes/visual/l_shoulder.stl" />
    <mesh name="urdf_l_upper_arm_simplified" content_type="model/stl" file="/home/alex/Documents/GitHub/ldr-harambe-arms-sim2real/src/robot_description/full_robot_description/meshes/visual/urdf_l_upper_arm_simplified.stl" />
    <mesh name="urdf_l_elbow_simplified" content_type="model/stl" file="/home/alex/Documents/GitHub/ldr-harambe-arms-sim2real/src/robot_description/full_robot_description/meshes/visual/urdf_l_elbow_simplified.stl" />
    <mesh name="urdf_l_upper_forearm_simplified" content_type="model/stl" file="/home/alex/Documents/GitHub/ldr-harambe-arms-sim2real/src/robot_description/full_robot_description/meshes/visual/urdf_l_upper_forearm_simplified.stl" />
    <mesh name="urdf_l_lower_forearm_simplified" content_type="model/stl" file="/home/alex/Documents/GitHub/ldr-harambe-arms-sim2real/src/robot_description/full_robot_description/meshes/visual/urdf_l_lower_forearm_simplified.stl" />
    <mesh name="l_wrist" content_type="model/stl" file="/home/alex/Documents/GitHub/ldr-harambe-arms-sim2real/src/robot_description/full_robot_description/meshes/visual/l_wrist.stl" />
    <mesh name="r_shoulder" content_type="model/stl" file="/home/alex/Documents/GitHub/ldr-harambe-arms-sim2real/src/robot_description/full_robot_description/meshes/visual/r_shoulder.stl" />
    <mesh name="r_upper_arm" content_type="model/stl" file="/home/alex/Documents/GitHub/ldr-harambe-arms-sim2real/src/robot_description/full_robot_description/meshes/visual/r_upper_arm.stl" />
    <mesh name="r_elbow" content_type="model/stl" file="/home/alex/Documents/GitHub/ldr-harambe-arms-sim2real/src/robot_description/full_robot_description/meshes/visual/r_elbow.stl" />
    <mesh name="r_upper_forearm" content_type="model/stl" file="/home/alex/Documents/GitHub/ldr-harambe-arms-sim2real/src/robot_description/full_robot_description/meshes/visual/r_upper_forearm.stl" />
    <mesh name="r_lower_forearm" content_type="model/stl" file="/home/alex/Documents/GitHub/ldr-harambe-arms-sim2real/src/robot_description/full_robot_description/meshes/visual/r_lower_forearm.stl" />
    <mesh name="r_wrist" content_type="model/stl" file="/home/alex/Documents/GitHub/ldr-harambe-arms-sim2real/src/robot_description/full_robot_description/meshes/visual/r_wrist.stl" />
    <mesh name="hip" content_type="model/stl" file="/home/alex/Documents/GitHub/ldr-harambe-arms-sim2real/src/robot_description/full_robot_description/meshes/visual/hip.stl" />
    <mesh name="stopper_leg_28_75" content_type="model/stl" file="/home/alex/Documents/GitHub/ldr-harambe-arms-sim2real/src/robot_description/full_robot_description/meshes/visual/stopper_leg_28_75.stl" />
    <mesh name="l_upper_femur" content_type="model/stl" file="/home/alex/Documents/GitHub/ldr-harambe-arms-sim2real/src/robot_description/full_robot_description/meshes/visual/l_upper_femur.stl" />
    <mesh name="stopper_leg_22_5" content_type="model/stl" file="/home/alex/Documents/GitHub/ldr-harambe-arms-sim2real/src/robot_description/full_robot_description/meshes/visual/stopper_leg_22_5.stl" />
    <mesh name="lower_femur" content_type="model/stl" file="/home/alex/Documents/GitHub/ldr-harambe-arms-sim2real/src/robot_description/full_robot_description/meshes/visual/lower_femur.stl" />
    <mesh name="urdf_l_tibia_assembly" content_type="model/stl" file="/home/alex/Documents/GitHub/ldr-harambe-arms-sim2real/src/robot_description/full_robot_description/meshes/visual/urdf_l_tibia_assembly.stl" />
    <mesh name="urdf_ankle_assembly" content_type="model/stl" file="/home/alex/Documents/GitHub/ldr-harambe-arms-sim2real/src/robot_description/full_robot_description/meshes/visual/urdf_ankle_assembly.stl" />
    <mesh name="urdf_foot_assembly" content_type="model/stl" file="/home/alex/Documents/GitHub/ldr-harambe-arms-sim2real/src/robot_description/full_robot_description/meshes/visual/urdf_foot_assembly.stl" />
    <mesh name="r_upper_femur" content_type="model/stl" file="/home/alex/Documents/GitHub/ldr-harambe-arms-sim2real/src/robot_description/full_robot_description/meshes/visual/r_upper_femur.stl" />
    <mesh name="urdf_r_tibia_assembly" content_type="model/stl" file="/home/alex/Documents/GitHub/ldr-harambe-arms-sim2real/src/robot_description/full_robot_description/meshes/visual/urdf_r_tibia_assembly.stl" />
  </asset>
  <worldbody>
    <body name="urdf_base" pos="0 0 1.2085">
      <inertial pos="0.071983 -0.000707749 -0.396794" mass="5.734" diaginertia="0.029089 0.0240807 0.0160144" />
      <freejoint name="root" />
      <geom pos="0.070373 -0.000705351 -1.1821" quat="0.707105 0 0 -0.707108" type="mesh" rgba="0.980392 0.713725 0.00392157 1" mesh="b_base" />
      <geom pos="0.070373 -0.000705351 0.319901" quat="9.38184e-07 -0.707105 0.707108 -9.38187e-07" type="mesh" rgba="0.654902 0.823529 0.576471 1" mesh="plate_base_right" />
      <geom pos="0.070373 -0.000705351 -1.1821" quat="0.707105 0 0 -0.707108" type="mesh" rgba="0.231373 0.380392 0.705882 1" mesh="f_base" />
      <geom pos="0.070373 -0.000705351 -1.1821" quat="0.707105 0 0 -0.707108" type="mesh" rgba="0.764706 0.545098 0.803922 1" mesh="plate_base_left" />
      <geom pos="0.070373 -0.000705351 -1.1821" quat="0.707105 0 0 -0.707108" type="mesh" rgba="0.654902 0.584314 0.823529 1" mesh="plate_base_top" />
      <geom pos="0.070373 -0.000705351 -0.431099" quat="0.707105 0 0 -0.707108" type="mesh" rgba="0.615686 0.811765 0.929412 1" mesh="jockstrap" />
      <body name="urdf_simplified_torso" pos="0.070373 -0.000705351 -0.281099">
        <inertial pos="0.00199132 -4.19393e-05 0.328473" mass="5.90423" fullinertia="0.318197 0.294961 0.0735035 5.25211e-07 -0.00444278 9.73773e-05" />
        <joint name="waist_yaw_joint_X8" pos="0 0 0" axis="0 0 1" range="-1.57 1.57" armature="0.0577" limited="true" frictionloss="3.21" />
        <geom pos="0 0 0.26095" quat="0.707105 0 0 -0.707108" type="mesh" rgba="0.647059 0.647059 0.647059 1" mesh="urdf_simplified_torso" />
        <geom pos="4.11536e-05 -0.000384166 0.6725" quat="0.707105 0 0 -0.707108" type="mesh" rgba="0.737255 0.937255 0.917647 1" mesh="head" />
        <body name="urdf_l_shoulder_assembly" pos="0 0.1695 0.423977">
          <inertial pos="-0.00409836 0.0631966 -0.000544507" mass="1.246" fullinertia="0.00205876 0.00152408 0.00171602 -3.48871e-05 4.1195e-05 -7.63845e-06" />
          <joint name="left_shoulder_pitch_joint_X6" pos="0 0 0" axis="0 1 0" range="-3.02 1.69" armature="0.0254" limited="true" frictionloss="1.6" />
          <geom pos="-0.00129022 0.0502746 -0.000165439" quat="0.705787 0.0431688 -0.043169 -0.705789" type="mesh" rgba="0.615686 0.811765 0.929412 1" mesh="l_shoulder" />
          <body name="urdf_l_upper_arm_assembly" pos="0.0456571 0.07 0.00560611" quat="0.998135 0 -0.06105 0">
            <inertial pos="-0.0354438 0.0213187 -0.103332" mass="0.802" fullinertia="0.00190836 0.00203106 0.00107639 8.88428e-05 -0.000467525 0.000183116" />
            <joint name="left_shoulder_roll_joint_X6" pos="0 0 0" axis="1 0 0" range="-0.21 2.93" armature="0.0254" limited="true" frictionloss="1.6" />
            <geom pos="-0.0268697 0.0182152 -0.0914675" quat="0.918818 0.0965753 0.0400017 -0.380587" type="mesh" rgba="0.917647 0.917647 0.917647 1" mesh="urdf_l_upper_arm_simplified" />
            <body name="urdf_l_elbow_assembly" pos="-0.046 0.034306 -0.161394" quat="0.99444 0.104525 0.00133297 -0.0126919">
              <inertial pos="-0.004748 -0.00662541 -0.0710681" mass="1.109" fullinertia="0.00145153 0.00147549 0.00114035 5.51714e-05 -3.01713e-05 -7.59581e-05" />
              <joint name="left_shoulder_yaw_joint_X4" pos="0 0 0" axis="0 0 1" range="-1.75 2.97" armature="0.0389" limited="true" frictionloss="1.14" />
              <geom pos="-0.00676793 -0.0102107 -0.075" quat="0.334487 0.622994 0.334483 -0.622991" type="mesh" rgba="0.231373 0.380392 0.705882 1" mesh="urdf_l_elbow_simplified" />
              <body name="urdf_l_upper_forearm_assembly" pos="0.0193369 0.0291733 -0.075" quat="0.957432 -0.00275413 -0.00914002 -0.2885">
                <inertial pos="0.0267132 -0.0286559 -0.0999185" mass="0.707" fullinertia="0.00162524 0.00146156 0.000776911 9.29307e-05 0.000226906 -0.000353662" />
                <joint name="left_elbow_pitch_joint_X6" pos="0 0 0" axis="0 1 0" range="-1.31 1.83" armature="0.0254" limited="true" frictionloss="1.6" />
                <geom pos="0.0285991 -0.035 -0.115512" quat="0.701905 0.0855982 -0.0855985 -0.701908" type="mesh" rgba="0.498039 0.498039 0.498039 1" mesh="urdf_l_upper_forearm_simplified" />
                <body name="urdf_l_lower_forearm_assembly" pos="0.0391735 -0.035 -0.158223" quat="0.945344 -0.0369251 -0.115285 0.302772">
                  <inertial pos="-0.00311766 0.00307025 -0.0515634" mass="0.618" fullinertia="0.000628386 0.000617293 0.000448744 -1.68351e-06 -2.8195e-05 -3.24981e-07" />
                  <joint name="left_wrist_yaw_joint_X4" pos="0 0 0" axis="0 0 1" range="-2.36 2.36" armature="0.0389" limited="true" frictionloss="1.14" />
                  <geom pos="-0.00732538 0.00522865 -0.0615" quat="0.62868 -0.628682 -0.323668 0.323666" type="mesh" rgba="0.980392 0.713725 0.00392157 1" mesh="urdf_l_lower_forearm_simplified" />
                  <body name="urdf_l_wrist_assembly" pos="0.0219762 -0.0156859 -0.0615" quat="0.945019 -0.117921 0.0377673 -0.302668">
                    <inertial pos="-0.0219307 0.0106852 -0.0421315" mass="0.098" fullinertia="0.000100785 0.000121426 9.6353e-05 8.20205e-06 -3.2373e-05 6.79922e-06" />
                    <joint name="left_wrist_roll_joint_X4" pos="0 0 0" axis="1 0 0" range="-1.57 1.57" armature="0.0389" limited="true" frictionloss="1.14" />
                    <geom pos="-0.0219314 0.0106852 -0.0421315" quat="0.701664 0.0875548 0.0875544 -0.701667" type="mesh" rgba="0.8 0.74902 0.913725 1" mesh="l_wrist" />
                    <body name="left_hand" pos="-0.034 0.015 -0.06">
                      <inertial pos="-0.003 -0.066 -0.002" mass="0.576" diaginertia="0.00012281 8.3832e-05 7.6663e-05" />
                      <geom type="box" size="0.04 0.025 0.07" rgba="0.5 0.5 0.5 0.3" contype="0" conaffinity="0" />
                    </body>
                  </body>
                </body>
              </body>
            </body>
          </body>
        </body>
        <body name="urdf_r_shoulder_assembly" pos="0 -0.1695 0.423977">
          <inertial pos="-0.0047018 -0.0660727 -0.000602826" mass="1.02" fullinertia="0.0013257 0.00104972 0.0011458 1.37507e-05 2.16644e-05 3.46311e-06" />
          <joint name="right_shoulder_pitch_joint_X6" pos="0 0 0" axis="0 1 0" range="-3.02 1.69" armature="0.0254" limited="true" frictionloss="1.6" />
          <geom pos="-0.00128021 -0.0501448 -0.000164156" quat="0.705787 0.0431688 -0.043169 -0.705789" type="mesh" rgba="0.615686 0.811765 0.929412 1" mesh="r_shoulder" />
          <body name="urdf_r_upper_arm_assembly" pos="0.0456571 -0.07 0.00560611" quat="0.998135 0 -0.06105 0">
            <inertial pos="-0.0347331 -0.0216398 -0.101809" mass="0.802" fullinertia="0.00188605 0.00200295 0.00106039 -9.73927e-05 -0.00045821 -0.000209822" />
            <joint name="right_shoulder_roll_joint_X6" pos="0 0 0" axis="1 0 0" range="-2.93 0.21" armature="0.0254" limited="true" frictionloss="1.6" />
            <geom pos="-0.025543 -0.0188222 -0.0885532" quat="0.703232 -0.0739117 -0.0739114 -0.703235" type="mesh" rgba="0.231373 0.380392 0.705882 1" mesh="r_upper_arm" />
            <body name="urdf_r_elbow_assembly" pos="-0.046 -0.0353444 -0.166285" quat="0.994441 -0.104518 0.00133208 0.0126917">
              <inertial pos="-0.00464628 0.00706688 -0.0612736" mass="1.109" fullinertia="0.00142737 0.00147543 0.00111817 -5.60371e-05 -3.53572e-05 4.92594e-05" />
              <joint name="right_shoulder_yaw_joint_X4" pos="0 0 0" axis="0 0 1" range="-2.97 1.75" armature="0.0389" limited="true" frictionloss="1.14" />
              <geom pos="0.000192865 -0.000269971 -0.0512953" quat="0.881046 0 0 -0.473031" type="mesh" rgba="0.796078 0.905882 0.745098 1" mesh="r_elbow" />
              <body name="urdf_r_upper_forearm_assembly" pos="0.0220994 -0.033341 -0.065" quat="0.957433 0.00275256 -0.00913491 0.288497">
                <inertial pos="0.0266786 0.0327896 -0.0982602" mass="0.707" fullinertia="0.00160609 0.0014499 0.000766591 -9.59596e-05 0.000238823 0.00033935" />
                <joint name="right_elbow_pitch_joint_X6" pos="0 0 0" axis="0 1 0" range="-1.31 1.83" armature="0.0254" limited="true" frictionloss="1.6" />
                <geom pos="0.0247724 0.0254856 -0.0806199" quat="0.701905 0.0856045 -0.0856048 -0.701907" type="mesh" rgba="0.890196 0.698039 0.639216 1" mesh="r_upper_forearm" />
                <body name="urdf_r_lower_forearm_assembly" pos="0.0403774 0.04 -0.163076" quat="0.945344 0.036924 -0.115291 -0.302768">
                  <inertial pos="-0.00325453 -0.0023229 -0.046852" mass="0.618" fullinertia="0.000617744 0.000618165 0.000437775 -6.12409e-07 -3.11927e-05 -2.22632e-05" />
                  <joint name="right_wrist_yaw_joint_X4" pos="0 0 0" axis="0 0 1" range="-2.36 2.36" armature="0.0389" limited="true" frictionloss="1.14" />
                  <geom pos="0.00167509 0.00119554 -0.0333447" quat="0.889087 0 0 -0.457739" type="mesh" rgba="0.941176 0.87451 0.678431 1" mesh="r_lower_forearm" />
                  <body name="urdf_r_wrist_assembly" pos="0.0219763 0.0156857 -0.0565" quat="0.945021 0.117919 0.037766 0.302662">
                    <inertial pos="-0.0219123 -0.0106789 -0.0421059" mass="0.15" fullinertia="0.000154293 0.000185908 0.00014762 -1.25537e-05 -4.9547e-05 -1.03834e-05" />
                    <joint name="right_wrist_roll_joint_X4" pos="0 0 0" axis="1 0 0" range="-1.57 1.57" armature="0.0389" limited="true" frictionloss="1.14" />
                    <geom pos="-0.0219316 -0.0106852 -0.0421314" quat="0.701664 -0.0875537 -0.0875534 -0.701667" type="mesh" rgba="0.8 0.74902 0.913725 1" mesh="r_wrist" />
                    <body name="right_hand" pos="-0.029 -0.011 -0.06">
                      <inertial pos="-0.003 -0.066 0.002" mass="0.576" diaginertia="0.00012281 8.3832e-05 7.6663e-05" />
                      <geom type="box" size="0.04 0.025 0.07" rgba="0.5 0.5 0.5 0.3" contype="0" conaffinity="0" />
                    </body>
                  </body>
                </body>
              </body>
            </body>
          </body>
        </body>
        <site name="Default_site" pos="0 0 0" size="0.005" />
        <site name="TorsoIMU_site" pos="0.0665 0 0.35" size="0.005" />
      </body>
      <body name="urdf_hip_assembly" pos="0.070373 0.0872946 -0.431099">
        <inertial pos="-0.00387043 0.0602754 -3.33254e-05" mass="1.829" fullinertia="0.00318486 0.00257781 0.00266816 -1.248e-05 2.39579e-07 -3.95097e-06" />
        <joint name="left_hip_pitch_joint_X8" pos="0 0 0" axis="0 1 0" range="-2.53 1.57" armature="0.0577" limited="true" frictionloss="3.21" />
        <geom pos="0.03 0.062 0" quat="0.500001 0.499997 -0.499999 -0.500002" type="mesh" rgba="0.498039 0.498039 0.498039 1" mesh="hip" />
        <body name="urdf_l_upper_femur_assembly" pos="0.053 0.062 0">
          <inertial pos="-0.0460989 0.000881037 -0.148514" mass="1.93" fullinertia="0.00524838 0.00568591 0.00347712 2.68214e-05 -0.000973448 1.37224e-06" />
          <joint name="left_hip_roll_joint_X8" pos="0 0 0" axis="1 0 0" range="-0.35 3.14" armature="0.0577" limited="true" frictionloss="1.6" />
          <geom pos="0.571524 0.417098 -0.118" quat="0.676659 0.205263 -0.676658 0.205267" type="mesh" rgba="0.972549 0.529412 0.00392157 1" mesh="stopper_leg_28_75" />
          <geom pos="-0.0257799 0.00151622 -0.111785" quat="0.707105 0 0 -0.707108" type="mesh" rgba="0.141176 0.694118 0.65098 1" mesh="l_upper_femur" />
          <body name="urdf_lower_femur_assembly" pos="-0.053 0 -0.217">
            <inertial pos="2.11243e-05 -0.00408754 -0.100571" mass="1.832" fullinertia="0.00401519 0.00435606 0.00266245 1.60501e-06 -3.40991e-06 -0.000112967" />
            <joint name="left_hip_yaw_joint_X8" pos="0 0 0" axis="0 0 1" range="-1.57 1.57" armature="0.0577" limited="true" frictionloss="1.6" />
            <geom pos="0.751 0.000165033 -0.1" quat="-3.60488e-07 -0.707107 -4.83421e-06 0.707107" type="mesh" rgba="0.768627 0.886275 0.952941 1" mesh="stopper_leg_22_5" />
            <geom pos="-4.57402e-09 0.00389134 -0.068766" quat="0.707109 0 0 -0.707105" type="mesh" rgba="0.380392 0.0470588 0.435294 1" mesh="lower_femur" />
            <body name="urdf_l_tibia_assembly" pos="-1.45947e-07 0.055 -0.111">
              <inertial pos="0.01449 -0.0488281 -0.199552" mass="2.216" fullinertia="0.0205548 0.0209762 0.00480101 0.000222702 0.00143905 -0.00195792" />
              <joint name="left_knee_joint_X8" pos="0 0 0" axis="0 1 0" range="-0.17 1.57" armature="0.0577" limited="true" frictionloss="1.14" />
              <geom pos="0.000678721 -0.0431371 -0.186264" quat="0.707105 0 0 -0.707108" type="mesh" rgba="0.615686 0.811765 0.929412 1" mesh="urdf_l_tibia_assembly" />
              <body name="urdf_ankle_assembly" pos="0 -0.051 -0.395">
                <inertial pos="0 -0.004 -0.0125426" quat="0.707107 0 0 0.707107" mass="0.0818219" diaginertia="1.69449e-05 2.15245e-05 1.25404e-05" />
                <joint name="left_ankle_pitch_joint_X4" pos="0 0 0" axis="0 1 0" range="-0.79 0.79" armature="0.0389" limited="true" frictionloss="1.14" />
                <geom pos="0 -0.004 -0.0125426" quat="0.707105 0 0 -0.707108" type="mesh" rgba="0.615686 0.811765 0.929412 1" mesh="urdf_ankle_assembly" />
                <body name="urdf_foot_assembly" pos="-0.012 -0.004 -0.028">
                  <inertial pos="0.0436027 8.11114e-08 -0.0200314" mass="0.309" fullinertia="0.000232433 0.00121361 0.00137693 -1.58776e-11 -9.83566e-06 -6.57666e-10" />
                  <joint name="left_ankle_roll_joint_X4" pos="0 0 0" axis="1 0 0" range="-0.79 0.79" armature="0.0389" limited="true" frictionloss="1.14" />
                  <geom pos="0.0436027 7.24764e-08 -0.0200314" quat="0.707105 0 0 -0.707108" type="mesh" rgba="0.615686 0.811765 0.929412 1" mesh="urdf_foot_assembly" friction="2.0 0.5 0.1" condim="4" />
                  <site name="LeftFoot_site" pos="0.043 0 -0.033" size="0.005" />
                </body>
              </body>
            </body>
          </body>
        </body>
      </body>
      <body name="urdf_hip_assembly_2" pos="0.070373 -0.0887054 -0.431099">
        <inertial pos="-0.00387043 -0.0602754 3.33254e-05" mass="1.829" fullinertia="0.00318486 0.00257781 0.00266816 1.248e-05 -2.39579e-07 -3.95097e-06" />
        <joint name="right_hip_pitch_joint_X8" pos="0 0 0" axis="0 1 0" range="-2.53 1.57" armature="0.0577" limited="true" frictionloss="3.21" />
        <geom pos="0.03 -0.062 0" quat="0.499998 -0.5 -0.500002 0.5" type="mesh" rgba="0.498039 0.498039 0.498039 1" mesh="hip" />
        <body name="urdf_r_upper_femur_assemby" pos="0.053 -0.062 0">
          <inertial pos="-0.0457109 -0.000406025 -0.147969" mass="1.912" fullinertia="0.00512969 0.00557257 0.00336728 -1.22901e-06 -0.000930002 5.18759e-05" />
          <joint name="right_hip_roll_joint_X8" pos="0 0 0" axis="1 0 0" range="-3.14 0.35" armature="0.0577" limited="true" frictionloss="1.6" />
          <geom pos="-0.0257799 -0.00151624 -0.111785" quat="0.707105 0 0 -0.707108" type="mesh" rgba="0.941176 0.87451 0.678431 1" mesh="r_upper_femur" />
          <body name="urdf_lower_femur_assembly_2" pos="-0.053 0 -0.217">
            <inertial pos="9.05521e-10 0.00357383 -0.101307" mass="1.817" fullinertia="0.00383469 0.00421827 0.00258541 -1.04286e-09 2.0768e-08 0.00019709" />
            <joint name="right_hip_yaw_joint_X8" pos="0 0 0" axis="0 0 1" range="-1.57 1.57" armature="0.0577" limited="true" frictionloss="1.6" />
            <geom pos="4.57402e-09 -0.00389134 -0.068766" quat="0.707105 0 0 0.707108" type="mesh" rgba="0.380392 0.0470588 0.435294 1" mesh="lower_femur" />
            <body name="urdf_r_tibia_assembly" pos="1.45947e-07 -0.055 -0.111">
              <inertial pos="0.0144959 0.0488304 -0.199574" mass="2.215" fullinertia="0.0205486 0.0209705 0.00479841 -0.000222584 0.00144134 0.00195651" />
              <joint name="right_knee_joint_X8" pos="0 0 0" axis="0 1 0" range="-0.17 1.57" armature="0.0577" limited="true" frictionloss="1.14" />
              <geom pos="0.000678806 0.0431372 -0.186264" quat="0.707105 0 0 -0.707108" type="mesh" rgba="0.615686 0.811765 0.929412 1" mesh="urdf_r_tibia_assembly" />
              <body name="urdf_ankle_assembly_2" pos="0 0.059 -0.395">
                <inertial pos="0 -0.004 -0.0125426" quat="0.707107 0 0 0.707107" mass="0.0818219" diaginertia="1.69449e-05 2.15245e-05 1.25404e-05" />
                <joint name="right_ankle_pitch_joint_X4" pos="0 0 0" axis="0 1 0" range="-0.79 0.79" armature="0.0389" limited="true" frictionloss="1.14" />
                <geom pos="0 -0.004 -0.0125426" quat="0.707105 0 0 -0.707108" type="mesh" rgba="0.615686 0.811765 0.929412 1" mesh="urdf_ankle_assembly" />
                <body name="urdf_foot_assembly_2" pos="-0.012 -0.004 -0.028">
                  <inertial pos="0.0436027 8.11114e-08 -0.0200314" mass="0.309" fullinertia="0.000232433 0.00121361 0.00137693 -1.58776e-11 -9.83566e-06 -6.57666e-10" />
                  <joint name="right_ankle_roll_joint_X4" pos="0 0 0" axis="1 0 0" range="-0.79 0.79" armature="0.0389" limited="true" frictionloss="1.14" />
                  <geom pos="0.0436027 7.24764e-08 -0.0200314" quat="0.707105 0 0 -0.707108" type="mesh" rgba="0.615686 0.811765 0.929412 1" mesh="urdf_foot_assembly" friction="2.0 0.5 0.1" condim="4" />
                  <site name="RightFoot_site" pos="0.043 0 -0.033" size="0.005" />
                </body>
              </body>
            </body>
          </body>
        </body>
      </body>
      <site name="Base_site" pos="0 0 0" size="0.005" />
      <site name="PelvisIMU_site" pos="0.1069 -0.0007 -0.4707" size="0.005" />
    </body>
  </worldbody>
  <contact>
    <exclude body1="urdf_ankle_assembly" body2="urdf_ankle_assembly_2" />
    <exclude body1="urdf_ankle_assembly" body2="urdf_base" />
    <exclude body1="urdf_ankle_assembly" body2="urdf_foot_assembly" />
    <exclude body1="urdf_ankle_assembly" body2="urdf_foot_assembly_2" />
    <exclude body1="urdf_ankle_assembly" body2="urdf_hip_assembly" />
    <exclude body1="urdf_ankle_assembly" body2="urdf_hip_assembly_2" />
    <exclude body1="urdf_ankle_assembly" body2="urdf_l_elbow_assembly" />
    <exclude body1="urdf_ankle_assembly" body2="urdf_l_lower_forearm_assembly" />
    <exclude body1="urdf_ankle_assembly" body2="urdf_l_shoulder_assembly" />
    <exclude body1="urdf_ankle_assembly" body2="urdf_l_tibia_assembly" />
    <exclude body1="urdf_ankle_assembly" body2="urdf_l_upper_arm_assembly" />
    <exclude body1="urdf_ankle_assembly" body2="urdf_l_upper_femur_assembly" />
    <exclude body1="urdf_ankle_assembly" body2="urdf_l_upper_forearm_assembly" />
    <exclude body1="urdf_ankle_assembly" body2="urdf_l_wrist_assembly" />
    <exclude body1="urdf_ankle_assembly" body2="urdf_lower_femur_assembly" />
    <exclude body1="urdf_ankle_assembly" body2="urdf_lower_femur_assembly_2" />
    <exclude body1="urdf_ankle_assembly" body2="urdf_r_elbow_assembly" />
    <exclude body1="urdf_ankle_assembly" body2="urdf_r_lower_forearm_assembly" />
    <exclude body1="urdf_ankle_assembly" body2="urdf_r_shoulder_assembly" />
    <exclude body1="urdf_ankle_assembly" body2="urdf_r_tibia_assembly" />
    <exclude body1="urdf_ankle_assembly" body2="urdf_r_upper_arm_assembly" />
    <exclude body1="urdf_ankle_assembly" body2="urdf_r_upper_femur_assemby" />
    <exclude body1="urdf_ankle_assembly" body2="urdf_r_upper_forearm_assembly" />
    <exclude body1="urdf_ankle_assembly" body2="urdf_r_wrist_assembly" />
    <exclude body1="urdf_ankle_assembly" body2="urdf_simplified_torso" />
    <exclude body1="urdf_ankle_assembly_2" body2="urdf_base" />
    <exclude body1="urdf_ankle_assembly_2" body2="urdf_foot_assembly" />
    <exclude body1="urdf_ankle_assembly_2" body2="urdf_foot_assembly_2" />
    <exclude body1="urdf_ankle_assembly_2" body2="urdf_hip_assembly" />
    <exclude body1="urdf_ankle_assembly_2" body2="urdf_hip_assembly_2" />
    <exclude body1="urdf_ankle_assembly_2" body2="urdf_l_elbow_assembly" />
    <exclude body1="urdf_ankle_assembly_2" body2="urdf_l_lower_forearm_assembly" />
    <exclude body1="urdf_ankle_assembly_2" body2="urdf_l_shoulder_assembly" />
    <exclude body1="urdf_ankle_assembly_2" body2="urdf_l_tibia_assembly" />
    <exclude body1="urdf_ankle_assembly_2" body2="urdf_l_upper_arm_assembly" />
    <exclude body1="urdf_ankle_assembly_2" body2="urdf_l_upper_femur_assembly" />
    <exclude body1="urdf_ankle_assembly_2" body2="urdf_l_upper_forearm_assembly" />
    <exclude body1="urdf_ankle_assembly_2" body2="urdf_l_wrist_assembly" />
    <exclude body1="urdf_ankle_assembly_2" body2="urdf_lower_femur_assembly" />
    <exclude body1="urdf_ankle_assembly_2" body2="urdf_lower_femur_assembly_2" />
    <exclude body1="urdf_ankle_assembly_2" body2="urdf_r_elbow_assembly" />
    <exclude body1="urdf_ankle_assembly_2" body2="urdf_r_lower_forearm_assembly" />
    <exclude body1="urdf_ankle_assembly_2" body2="urdf_r_shoulder_assembly" />
    <exclude body1="urdf_ankle_assembly_2" body2="urdf_r_tibia_assembly" />
    <exclude body1="urdf_ankle_assembly_2" body2="urdf_r_upper_arm_assembly" />
    <exclude body1="urdf_ankle_assembly_2" body2="urdf_r_upper_femur_assemby" />
    <exclude body1="urdf_ankle_assembly_2" body2="urdf_r_upper_forearm_assembly" />
    <exclude body1="urdf_ankle_assembly_2" body2="urdf_r_wrist_assembly" />
    <exclude body1="urdf_ankle_assembly_2" body2="urdf_simplified_torso" />
    <exclude body1="urdf_base" body2="urdf_foot_assembly" />
    <exclude body1="urdf_base" body2="urdf_foot_assembly_2" />
    <exclude body1="urdf_base" body2="urdf_hip_assembly" />
    <exclude body1="urdf_base" body2="urdf_hip_assembly_2" />
    <exclude body1="urdf_base" body2="urdf_l_elbow_assembly" />
    <exclude body1="urdf_base" body2="urdf_l_lower_forearm_assembly" />
    <exclude body1="urdf_base" body2="urdf_l_shoulder_assembly" />
    <exclude body1="urdf_base" body2="urdf_l_tibia_assembly" />
    <exclude body1="urdf_base" body2="urdf_l_upper_arm_assembly" />
    <exclude body1="urdf_base" body2="urdf_l_upper_femur_assembly" />
    <exclude body1="urdf_base" body2="urdf_l_upper_forearm_assembly" />
    <exclude body1="urdf_base" body2="urdf_l_wrist_assembly" />
    <exclude body1="urdf_base" body2="urdf_lower_femur_assembly" />
    <exclude body1="urdf_base" body2="urdf_lower_femur_assembly_2" />
    <exclude body1="urdf_base" body2="urdf_r_elbow_assembly" />
    <exclude body1="urdf_base" body2="urdf_r_lower_forearm_assembly" />
    <exclude body1="urdf_base" body2="urdf_r_shoulder_assembly" />
    <exclude body1="urdf_base" body2="urdf_r_tibia_assembly" />
    <exclude body1="urdf_base" body2="urdf_r_upper_arm_assembly" />
    <exclude body1="urdf_base" body2="urdf_r_upper_femur_assemby" />
    <exclude body1="urdf_base" body2="urdf_r_upper_forearm_assembly" />
    <exclude body1="urdf_base" body2="urdf_r_wrist_assembly" />
    <exclude body1="urdf_base" body2="urdf_simplified_torso" />
    <exclude body1="urdf_foot_assembly" body2="urdf_foot_assembly_2" />
    <exclude body1="urdf_foot_assembly" body2="urdf_hip_assembly" />
    <exclude body1="urdf_foot_assembly" body2="urdf_hip_assembly_2" />
    <exclude body1="urdf_foot_assembly" body2="urdf_l_elbow_assembly" />
    <exclude body1="urdf_foot_assembly" body2="urdf_l_lower_forearm_assembly" />
    <exclude body1="urdf_foot_assembly" body2="urdf_l_shoulder_assembly" />
    <exclude body1="urdf_foot_assembly" body2="urdf_l_tibia_assembly" />
    <exclude body1="urdf_foot_assembly" body2="urdf_l_upper_arm_assembly" />
    <exclude body1="urdf_foot_assembly" body2="urdf_l_upper_femur_assembly" />
    <exclude body1="urdf_foot_assembly" body2="urdf_l_upper_forearm_assembly" />
    <exclude body1="urdf_foot_assembly" body2="urdf_l_wrist_assembly" />
    <exclude body1="urdf_foot_assembly" body2="urdf_lower_femur_assembly" />
    <exclude body1="urdf_foot_assembly" body2="urdf_lower_femur_assembly_2" />
    <exclude body1="urdf_foot_assembly" body2="urdf_r_elbow_assembly" />
    <exclude body1="urdf_foot_assembly" body2="urdf_r_lower_forearm_assembly" />
    <exclude body1="urdf_foot_assembly" body2="urdf_r_shoulder_assembly" />
    <exclude body1="urdf_foot_assembly" body2="urdf_r_tibia_assembly" />
    <exclude body1="urdf_foot_assembly" body2="urdf_r_upper_arm_assembly" />
    <exclude body1="urdf_foot_assembly" body2="urdf_r_upper_femur_assemby" />
    <exclude body1="urdf_foot_assembly" body2="urdf_r_upper_forearm_assembly" />
    <exclude body1="urdf_foot_assembly" body2="urdf_r_wrist_assembly" />
    <exclude body1="urdf_foot_assembly" body2="urdf_simplified_torso" />
    <exclude body1="urdf_foot_assembly_2" body2="urdf_hip_assembly" />
    <exclude body1="urdf_foot_assembly_2" body2="urdf_hip_assembly_2" />
    <exclude body1="urdf_foot_assembly_2" body2="urdf_l_elbow_assembly" />
    <exclude body1="urdf_foot_assembly_2" body2="urdf_l_lower_forearm_assembly" />
    <exclude body1="urdf_foot_assembly_2" body2="urdf_l_shoulder_assembly" />
    <exclude body1="urdf_foot_assembly_2" body2="urdf_l_tibia_assembly" />
    <exclude body1="urdf_foot_assembly_2" body2="urdf_l_upper_arm_assembly" />
    <exclude body1="urdf_foot_assembly_2" body2="urdf_l_upper_femur_assembly" />
    <exclude body1="urdf_foot_assembly_2" body2="urdf_l_upper_forearm_assembly" />
    <exclude body1="urdf_foot_assembly_2" body2="urdf_l_wrist_assembly" />
    <exclude body1="urdf_foot_assembly_2" body2="urdf_lower_femur_assembly" />
    <exclude body1="urdf_foot_assembly_2" body2="urdf_lower_femur_assembly_2" />
    <exclude body1="urdf_foot_assembly_2" body2="urdf_r_elbow_assembly" />
    <exclude body1="urdf_foot_assembly_2" body2="urdf_r_lower_forearm_assembly" />
    <exclude body1="urdf_foot_assembly_2" body2="urdf_r_shoulder_assembly" />
    <exclude body1="urdf_foot_assembly_2" body2="urdf_r_tibia_assembly" />
    <exclude body1="urdf_foot_assembly_2" body2="urdf_r_upper_arm_assembly" />
    <exclude body1="urdf_foot_assembly_2" body2="urdf_r_upper_femur_assemby" />
    <exclude body1="urdf_foot_assembly_2" body2="urdf_r_upper_forearm_assembly" />
    <exclude body1="urdf_foot_assembly_2" body2="urdf_r_wrist_assembly" />
    <exclude body1="urdf_foot_assembly_2" body2="urdf_simplified_torso" />
    <exclude body1="urdf_hip_assembly" body2="urdf_hip_assembly_2" />
    <exclude body1="urdf_hip_assembly" body2="urdf_l_elbow_assembly" />
    <exclude body1="urdf_hip_assembly" body2="urdf_l_lower_forearm_assembly" />
    <exclude body1="urdf_hip_assembly" body2="urdf_l_shoulder_assembly" />
    <exclude body1="urdf_hip_assembly" body2="urdf_l_tibia_assembly" />
    <exclude body1="urdf_hip_assembly" body2="urdf_l_upper_arm_assembly" />
    <exclude body1="urdf_hip_assembly" body2="urdf_l_upper_femur_assembly" />
    <exclude body1="urdf_hip_assembly" body2="urdf_l_upper_forearm_assembly" />
    <exclude body1="urdf_hip_assembly" body2="urdf_l_wrist_assembly" />
    <exclude body1="urdf_hip_assembly" body2="urdf_lower_femur_assembly" />
    <exclude body1="urdf_hip_assembly" body2="urdf_lower_femur_assembly_2" />
    <exclude body1="urdf_hip_assembly" body2="urdf_r_elbow_assembly" />
    <exclude body1="urdf_hip_assembly" body2="urdf_r_lower_forearm_assembly" />
    <exclude body1="urdf_hip_assembly" body2="urdf_r_shoulder_assembly" />
    <exclude body1="urdf_hip_assembly" body2="urdf_r_tibia_assembly" />
    <exclude body1="urdf_hip_assembly" body2="urdf_r_upper_arm_assembly" />
    <exclude body1="urdf_hip_assembly" body2="urdf_r_upper_femur_assemby" />
    <exclude body1="urdf_hip_assembly" body2="urdf_r_upper_forearm_assembly" />
    <exclude body1="urdf_hip_assembly" body2="urdf_r_wrist_assembly" />
    <exclude body1="urdf_hip_assembly" body2="urdf_simplified_torso" />
    <exclude body1="urdf_hip_assembly_2" body2="urdf_l_elbow_assembly" />
    <exclude body1="urdf_hip_assembly_2" body2="urdf_l_lower_forearm_assembly" />
    <exclude body1="urdf_hip_assembly_2" body2="urdf_l_shoulder_assembly" />
    <exclude body1="urdf_hip_assembly_2" body2="urdf_l_tibia_assembly" />
    <exclude body1="urdf_hip_assembly_2" body2="urdf_l_upper_arm_assembly" />
    <exclude body1="urdf_hip_assembly_2" body2="urdf_l_upper_femur_assembly" />
    <exclude body1="urdf_hip_assembly_2" body2="urdf_l_upper_forearm_assembly" />
    <exclude body1="urdf_hip_assembly_2" body2="urdf_l_wrist_assembly" />
    <exclude body1="urdf_hip_assembly_2" body2="urdf_lower_femur_assembly" />
    <exclude body1="urdf_hip_assembly_2" body2="urdf_lower_femur_assembly_2" />
    <exclude body1="urdf_hip_assembly_2" body2="urdf_r_elbow_assembly" />
    <exclude body1="urdf_hip_assembly_2" body2="urdf_r_lower_forearm_assembly" />
    <exclude body1="urdf_hip_assembly_2" body2="urdf_r_shoulder_assembly" />
    <exclude body1="urdf_hip_assembly_2" body2="urdf_r_tibia_assembly" />
    <exclude body1="urdf_hip_assembly_2" body2="urdf_r_upper_arm_assembly" />
    <exclude body1="urdf_hip_assembly_2" body2="urdf_r_upper_femur_assemby" />
    <exclude body1="urdf_hip_assembly_2" body2="urdf_r_upper_forearm_assembly" />
    <exclude body1="urdf_hip_assembly_2" body2="urdf_r_wrist_assembly" />
    <exclude body1="urdf_hip_assembly_2" body2="urdf_simplified_torso" />
    <exclude body1="urdf_l_elbow_assembly" body2="urdf_l_lower_forearm_assembly" />
    <exclude body1="urdf_l_elbow_assembly" body2="urdf_l_shoulder_assembly" />
    <exclude body1="urdf_l_elbow_assembly" body2="urdf_l_tibia_assembly" />
    <exclude body1="urdf_l_elbow_assembly" body2="urdf_l_upper_arm_assembly" />
    <exclude body1="urdf_l_elbow_assembly" body2="urdf_l_upper_femur_assembly" />
    <exclude body1="urdf_l_elbow_assembly" body2="urdf_l_upper_forearm_assembly" />
    <exclude body1="urdf_l_elbow_assembly" body2="urdf_l_wrist_assembly" />
    <exclude body1="urdf_l_elbow_assembly" body2="urdf_lower_femur_assembly" />
    <exclude body1="urdf_l_elbow_assembly" body2="urdf_lower_femur_assembly_2" />
    <exclude body1="urdf_l_elbow_assembly" body2="urdf_r_elbow_assembly" />
    <exclude body1="urdf_l_elbow_assembly" body2="urdf_r_lower_forearm_assembly" />
    <exclude body1="urdf_l_elbow_assembly" body2="urdf_r_shoulder_assembly" />
    <exclude body1="urdf_l_elbow_assembly" body2="urdf_r_tibia_assembly" />
    <exclude body1="urdf_l_elbow_assembly" body2="urdf_r_upper_arm_assembly" />
    <exclude body1="urdf_l_elbow_assembly" body2="urdf_r_upper_femur_assemby" />
    <exclude body1="urdf_l_elbow_assembly" body2="urdf_r_upper_forearm_assembly" />
    <exclude body1="urdf_l_elbow_assembly" body2="urdf_r_wrist_assembly" />
    <exclude body1="urdf_l_elbow_assembly" body2="urdf_simplified_torso" />
    <exclude body1="urdf_l_lower_forearm_assembly" body2="urdf_l_shoulder_assembly" />
    <exclude body1="urdf_l_lower_forearm_assembly" body2="urdf_l_tibia_assembly" />
    <exclude body1="urdf_l_lower_forearm_assembly" body2="urdf_l_upper_arm_assembly" />
    <exclude body1="urdf_l_lower_forearm_assembly" body2="urdf_l_upper_femur_assembly" />
    <exclude body1="urdf_l_lower_forearm_assembly" body2="urdf_l_upper_forearm_assembly" />
    <exclude body1="urdf_l_lower_forearm_assembly" body2="urdf_l_wrist_assembly" />
    <exclude body1="urdf_l_lower_forearm_assembly" body2="urdf_lower_femur_assembly" />
    <exclude body1="urdf_l_lower_forearm_assembly" body2="urdf_lower_femur_assembly_2" />
    <exclude body1="urdf_l_lower_forearm_assembly" body2="urdf_r_elbow_assembly" />
    <exclude body1="urdf_l_lower_forearm_assembly" body2="urdf_r_lower_forearm_assembly" />
    <exclude body1="urdf_l_lower_forearm_assembly" body2="urdf_r_shoulder_assembly" />
    <exclude body1="urdf_l_lower_forearm_assembly" body2="urdf_r_tibia_assembly" />
    <exclude body1="urdf_l_lower_forearm_assembly" body2="urdf_r_upper_arm_assembly" />
    <exclude body1="urdf_l_lower_forearm_assembly" body2="urdf_r_upper_femur_assemby" />
    <exclude body1="urdf_l_lower_forearm_assembly" body2="urdf_r_upper_forearm_assembly" />
    <exclude body1="urdf_l_lower_forearm_assembly" body2="urdf_r_wrist_assembly" />
    <exclude body1="urdf_l_lower_forearm_assembly" body2="urdf_simplified_torso" />
    <exclude body1="urdf_l_shoulder_assembly" body2="urdf_l_tibia_assembly" />
    <exclude body1="urdf_l_shoulder_assembly" body2="urdf_l_upper_arm_assembly" />
    <exclude body1="urdf_l_shoulder_assembly" body2="urdf_l_upper_femur_assembly" />
    <exclude body1="urdf_l_shoulder_assembly" body2="urdf_l_upper_forearm_assembly" />
    <exclude body1="urdf_l_shoulder_assembly" body2="urdf_l_wrist_assembly" />
    <exclude body1="urdf_l_shoulder_assembly" body2="urdf_lower_femur_assembly" />
    <exclude body1="urdf_l_shoulder_assembly" body2="urdf_lower_femur_assembly_2" />
    <exclude body1="urdf_l_shoulder_assembly" body2="urdf_r_elbow_assembly" />
    <exclude body1="urdf_l_shoulder_assembly" body2="urdf_r_lower_forearm_assembly" />
    <exclude body1="urdf_l_shoulder_assembly" body2="urdf_r_shoulder_assembly" />
    <exclude body1="urdf_l_shoulder_assembly" body2="urdf_r_tibia_assembly" />
    <exclude body1="urdf_l_shoulder_assembly" body2="urdf_r_upper_arm_assembly" />
    <exclude body1="urdf_l_shoulder_assembly" body2="urdf_r_upper_femur_assemby" />
    <exclude body1="urdf_l_shoulder_assembly" body2="urdf_r_upper_forearm_assembly" />
    <exclude body1="urdf_l_shoulder_assembly" body2="urdf_r_wrist_assembly" />
    <exclude body1="urdf_l_shoulder_assembly" body2="urdf_simplified_torso" />
    <exclude body1="urdf_l_tibia_assembly" body2="urdf_l_upper_arm_assembly" />
    <exclude body1="urdf_l_tibia_assembly" body2="urdf_l_upper_femur_assembly" />
    <exclude body1="urdf_l_tibia_assembly" body2="urdf_l_upper_forearm_assembly" />
    <exclude body1="urdf_l_tibia_assembly" body2="urdf_l_wrist_assembly" />
    <exclude body1="urdf_l_tibia_assembly" body2="urdf_lower_femur_assembly" />
    <exclude body1="urdf_l_tibia_assembly" body2="urdf_lower_femur_assembly_2" />
    <exclude body1="urdf_l_tibia_assembly" body2="urdf_r_elbow_assembly" />
    <exclude body1="urdf_l_tibia_assembly" body2="urdf_r_lower_forearm_assembly" />
    <exclude body1="urdf_l_tibia_assembly" body2="urdf_r_shoulder_assembly" />
    <exclude body1="urdf_l_tibia_assembly" body2="urdf_r_tibia_assembly" />
    <exclude body1="urdf_l_tibia_assembly" body2="urdf_r_upper_arm_assembly" />
    <exclude body1="urdf_l_tibia_assembly" body2="urdf_r_upper_femur_assemby" />
    <exclude body1="urdf_l_tibia_assembly" body2="urdf_r_upper_forearm_assembly" />
    <exclude body1="urdf_l_tibia_assembly" body2="urdf_r_wrist_assembly" />
    <exclude body1="urdf_l_tibia_assembly" body2="urdf_simplified_torso" />
    <exclude body1="urdf_l_upper_arm_assembly" body2="urdf_l_upper_femur_assembly" />
    <exclude body1="urdf_l_upper_arm_assembly" body2="urdf_l_upper_forearm_assembly" />
    <exclude body1="urdf_l_upper_arm_assembly" body2="urdf_l_wrist_assembly" />
    <exclude body1="urdf_l_upper_arm_assembly" body2="urdf_lower_femur_assembly" />
    <exclude body1="urdf_l_upper_arm_assembly" body2="urdf_lower_femur_assembly_2" />
    <exclude body1="urdf_l_upper_arm_assembly" body2="urdf_r_elbow_assembly" />
    <exclude body1="urdf_l_upper_arm_assembly" body2="urdf_r_lower_forearm_assembly" />
    <exclude body1="urdf_l_upper_arm_assembly" body2="urdf_r_shoulder_assembly" />
    <exclude body1="urdf_l_upper_arm_assembly" body2="urdf_r_tibia_assembly" />
    <exclude body1="urdf_l_upper_arm_assembly" body2="urdf_r_upper_arm_assembly" />
    <exclude body1="urdf_l_upper_arm_assembly" body2="urdf_r_upper_femur_assemby" />
    <exclude body1="urdf_l_upper_arm_assembly" body2="urdf_r_upper_forearm_assembly" />
    <exclude body1="urdf_l_upper_arm_assembly" body2="urdf_r_wrist_assembly" />
    <exclude body1="urdf_l_upper_arm_assembly" body2="urdf_simplified_torso" />
    <exclude body1="urdf_l_upper_femur_assembly" body2="urdf_l_upper_forearm_assembly" />
    <exclude body1="urdf_l_upper_femur_assembly" body2="urdf_l_wrist_assembly" />
    <exclude body1="urdf_l_upper_femur_assembly" body2="urdf_lower_femur_assembly" />
    <exclude body1="urdf_l_upper_femur_assembly" body2="urdf_lower_femur_assembly_2" />
    <exclude body1="urdf_l_upper_femur_assembly" body2="urdf_r_elbow_assembly" />
    <exclude body1="urdf_l_upper_femur_assembly" body2="urdf_r_lower_forearm_assembly" />
    <exclude body1="urdf_l_upper_femur_assembly" body2="urdf_r_shoulder_assembly" />
    <exclude body1="urdf_l_upper_femur_assembly" body2="urdf_r_tibia_assembly" />
    <exclude body1="urdf_l_upper_femur_assembly" body2="urdf_r_upper_arm_assembly" />
    <exclude body1="urdf_l_upper_femur_assembly" body2="urdf_r_upper_femur_assemby" />
    <exclude body1="urdf_l_upper_femur_assembly" body2="urdf_r_upper_forearm_assembly" />
    <exclude body1="urdf_l_upper_femur_assembly" body2="urdf_r_wrist_assembly" />
    <exclude body1="urdf_l_upper_femur_assembly" body2="urdf_simplified_torso" />
    <exclude body1="urdf_l_upper_forearm_assembly" body2="urdf_l_wrist_assembly" />
    <exclude body1="urdf_l_upper_forearm_assembly" body2="urdf_lower_femur_assembly" />
    <exclude body1="urdf_l_upper_forearm_assembly" body2="urdf_lower_femur_assembly_2" />
    <exclude body1="urdf_l_upper_forearm_assembly" body2="urdf_r_elbow_assembly" />
    <exclude body1="urdf_l_upper_forearm_assembly" body2="urdf_r_lower_forearm_assembly" />
    <exclude body1="urdf_l_upper_forearm_assembly" body2="urdf_r_shoulder_assembly" />
    <exclude body1="urdf_l_upper_forearm_assembly" body2="urdf_r_tibia_assembly" />
    <exclude body1="urdf_l_upper_forearm_assembly" body2="urdf_r_upper_arm_assembly" />
    <exclude body1="urdf_l_upper_forearm_assembly" body2="urdf_r_upper_femur_assemby" />
    <exclude body1="urdf_l_upper_forearm_assembly" body2="urdf_r_upper_forearm_assembly" />
    <exclude body1="urdf_l_upper_forearm_assembly" body2="urdf_r_wrist_assembly" />
    <exclude body1="urdf_l_upper_forearm_assembly" body2="urdf_simplified_torso" />
    <exclude body1="urdf_l_wrist_assembly" body2="urdf_lower_femur_assembly" />
    <exclude body1="urdf_l_wrist_assembly" body2="urdf_lower_femur_assembly_2" />
    <exclude body1="urdf_l_wrist_assembly" body2="urdf_r_elbow_assembly" />
    <exclude body1="urdf_l_wrist_assembly" body2="urdf_r_lower_forearm_assembly" />
    <exclude body1="urdf_l_wrist_assembly" body2="urdf_r_shoulder_assembly" />
    <exclude body1="urdf_l_wrist_assembly" body2="urdf_r_tibia_assembly" />
    <exclude body1="urdf_l_wrist_assembly" body2="urdf_r_upper_arm_assembly" />
    <exclude body1="urdf_l_wrist_assembly" body2="urdf_r_upper_femur_assemby" />
    <exclude body1="urdf_l_wrist_assembly" body2="urdf_r_upper_forearm_assembly" />
    <exclude body1="urdf_l_wrist_assembly" body2="urdf_r_wrist_assembly" />
    <exclude body1="urdf_l_wrist_assembly" body2="urdf_simplified_torso" />
    <exclude body1="urdf_lower_femur_assembly" body2="urdf_lower_femur_assembly_2" />
    <exclude body1="urdf_lower_femur_assembly" body2="urdf_r_elbow_assembly" />
    <exclude body1="urdf_lower_femur_assembly" body2="urdf_r_lower_forearm_assembly" />
    <exclude body1="urdf_lower_femur_assembly" body2="urdf_r_shoulder_assembly" />
    <exclude body1="urdf_lower_femur_assembly" body2="urdf_r_tibia_assembly" />
    <exclude body1="urdf_lower_femur_assembly" body2="urdf_r_upper_arm_assembly" />
    <exclude body1="urdf_lower_femur_assembly" body2="urdf_r_upper_femur_assemby" />
    <exclude body1="urdf_lower_femur_assembly" body2="urdf_r_upper_forearm_assembly" />
    <exclude body1="urdf_lower_femur_assembly" body2="urdf_r_wrist_assembly" />
    <exclude body1="urdf_lower_femur_assembly" body2="urdf_simplified_torso" />
    <exclude body1="urdf_lower_femur_assembly_2" body2="urdf_r_elbow_assembly" />
    <exclude body1="urdf_lower_femur_assembly_2" body2="urdf_r_lower_forearm_assembly" />
    <exclude body1="urdf_lower_femur_assembly_2" body2="urdf_r_shoulder_assembly" />
    <exclude body1="urdf_lower_femur_assembly_2" body2="urdf_r_tibia_assembly" />
    <exclude body1="urdf_lower_femur_assembly_2" body2="urdf_r_upper_arm_assembly" />
    <exclude body1="urdf_lower_femur_assembly_2" body2="urdf_r_upper_femur_assemby" />
    <exclude body1="urdf_lower_femur_assembly_2" body2="urdf_r_upper_forearm_assembly" />
    <exclude body1="urdf_lower_femur_assembly_2" body2="urdf_r_wrist_assembly" />
    <exclude body1="urdf_lower_femur_assembly_2" body2="urdf_simplified_torso" />
    <exclude body1="urdf_r_elbow_assembly" body2="urdf_r_lower_forearm_assembly" />
    <exclude body1="urdf_r_elbow_assembly" body2="urdf_r_shoulder_assembly" />
    <exclude body1="urdf_r_elbow_assembly" body2="urdf_r_tibia_assembly" />
    <exclude body1="urdf_r_elbow_assembly" body2="urdf_r_upper_arm_assembly" />
    <exclude body1="urdf_r_elbow_assembly" body2="urdf_r_upper_femur_assemby" />
    <exclude body1="urdf_r_elbow_assembly" body2="urdf_r_upper_forearm_assembly" />
    <exclude body1="urdf_r_elbow_assembly" body2="urdf_r_wrist_assembly" />
    <exclude body1="urdf_r_elbow_assembly" body2="urdf_simplified_torso" />
    <exclude body1="urdf_r_lower_forearm_assembly" body2="urdf_r_shoulder_assembly" />
    <exclude body1="urdf_r_lower_forearm_assembly" body2="urdf_r_tibia_assembly" />
    <exclude body1="urdf_r_lower_forearm_assembly" body2="urdf_r_upper_arm_assembly" />
    <exclude body1="urdf_r_lower_forearm_assembly" body2="urdf_r_upper_femur_assemby" />
    <exclude body1="urdf_r_lower_forearm_assembly" body2="urdf_r_upper_forearm_assembly" />
    <exclude body1="urdf_r_lower_forearm_assembly" body2="urdf_r_wrist_assembly" />
    <exclude body1="urdf_r_lower_forearm_assembly" body2="urdf_simplified_torso" />
    <exclude body1="urdf_r_shoulder_assembly" body2="urdf_r_tibia_assembly" />
    <exclude body1="urdf_r_shoulder_assembly" body2="urdf_r_upper_arm_assembly" />
    <exclude body1="urdf_r_shoulder_assembly" body2="urdf_r_upper_femur_assemby" />
    <exclude body1="urdf_r_shoulder_assembly" body2="urdf_r_upper_forearm_assembly" />
    <exclude body1="urdf_r_shoulder_assembly" body2="urdf_r_wrist_assembly" />
    <exclude body1="urdf_r_shoulder_assembly" body2="urdf_simplified_torso" />
    <exclude body1="urdf_r_tibia_assembly" body2="urdf_r_upper_arm_assembly" />
    <exclude body1="urdf_r_tibia_assembly" body2="urdf_r_upper_femur_assemby" />
    <exclude body1="urdf_r_tibia_assembly" body2="urdf_r_upper_forearm_assembly" />
    <exclude body1="urdf_r_tibia_assembly" body2="urdf_r_wrist_assembly" />
    <exclude body1="urdf_r_tibia_assembly" body2="urdf_simplified_torso" />
    <exclude body1="urdf_r_upper_arm_assembly" body2="urdf_r_upper_femur_assemby" />
    <exclude body1="urdf_r_upper_arm_assembly" body2="urdf_r_upper_forearm_assembly" />
    <exclude body1="urdf_r_upper_arm_assembly" body2="urdf_r_wrist_assembly" />
    <exclude body1="urdf_r_upper_arm_assembly" body2="urdf_simplified_torso" />
    <exclude body1="urdf_r_upper_femur_assemby" body2="urdf_r_upper_forearm_assembly" />
    <exclude body1="urdf_r_upper_femur_assemby" body2="urdf_r_wrist_assembly" />
    <exclude body1="urdf_r_upper_femur_assemby" body2="urdf_simplified_torso" />
    <exclude body1="urdf_r_upper_forearm_assembly" body2="urdf_r_wrist_assembly" />
    <exclude body1="urdf_r_upper_forearm_assembly" body2="urdf_simplified_torso" />
    <exclude body1="urdf_r_wrist_assembly" body2="urdf_simplified_torso" />
  </contact>
  <option timestep="0.001" impratio="10" solver="Newton" iterations="50" tolerance="1e-10" noslip_iterations="10" />
  <default>
    <geom friction="2.0 0.5 0.1" condim="4" solref="0.002 1" solimp="0.98 0.99 0.0001 0.5 2" />
  </default>
  <actuator>
    <motor name="left_shoulder_pitch_joint_X6" joint="left_shoulder_pitch_joint_X6" ctrlrange="-23 23" ctrllimited="true" />
    <motor name="left_shoulder_roll_joint_X6" joint="left_shoulder_roll_joint_X6" ctrlrange="-23 23" ctrllimited="true" />
    <motor name="left_shoulder_yaw_joint_X4" joint="left_shoulder_yaw_joint_X4" ctrlrange="-12.075 12.075" ctrllimited="true" />
    <motor name="left_elbow_pitch_joint_X6" joint="left_elbow_pitch_joint_X6" ctrlrange="-23 23" ctrllimited="true" />
    <motor name="left_wrist_yaw_joint_X4" joint="left_wrist_yaw_joint_X4" ctrlrange="-12.075 12.075" ctrllimited="true" />
    <motor name="left_wrist_roll_joint_X4" joint="left_wrist_roll_joint_X4" ctrlrange="-12.075 12.075" ctrllimited="true" />
    <motor name="right_shoulder_pitch_joint_X6" joint="right_shoulder_pitch_joint_X6" ctrlrange="-23 23" ctrllimited="true" />
    <motor name="right_shoulder_roll_joint_X6" joint="right_shoulder_roll_joint_X6" ctrlrange="-23 23" ctrllimited="true" />
    <motor name="right_shoulder_yaw_joint_X4" joint="right_shoulder_yaw_joint_X4" ctrlrange="-12.075 12.075" ctrllimited="true" />
    <motor name="right_elbow_pitch_joint_X6" joint="right_elbow_pitch_joint_X6" ctrlrange="-23 23" ctrllimited="true" />
    <motor name="right_wrist_yaw_joint_X4" joint="right_wrist_yaw_joint_X4" ctrlrange="-12.075 12.075" ctrllimited="true" />
    <motor name="right_wrist_roll_joint_X4" joint="right_wrist_roll_joint_X4" ctrlrange="-12.075 12.075" ctrllimited="true" />
    <motor name="waist_yaw_joint_X8" joint="waist_yaw_joint_X8" ctrlrange="-72 72" ctrllimited="true" />
    <motor name="left_hip_pitch_joint_X8" joint="left_hip_pitch_joint_X8" ctrlrange="-72 72" ctrllimited="true" />
    <motor name="left_hip_roll_joint_X8" joint="left_hip_roll_joint_X8" ctrlrange="-72 72" ctrllimited="true" />
    <motor name="left_hip_yaw_joint_X8" joint="left_hip_yaw_joint_X8" ctrlrange="-72 72" ctrllimited="true" />
    <motor name="left_knee_joint_X8" joint="left_knee_joint_X8" ctrlrange="-72 72" ctrllimited="true" />
    <motor name="left_ankle_pitch_joint_X4" joint="left_ankle_pitch_joint_X4" ctrlrange="-96.6 96.6" ctrllimited="true" />
    <motor name="left_ankle_roll_joint_X4" joint="left_ankle_roll_joint_X4" ctrlrange="-28.98 28.98" ctrllimited="true" />
    <motor name="right_hip_pitch_joint_X8" joint="right_hip_pitch_joint_X8" ctrlrange="-72 72" ctrllimited="true" />
    <motor name="right_hip_roll_joint_X8" joint="right_hip_roll_joint_X8" ctrlrange="-72 72" ctrllimited="true" />
    <motor name="right_hip_yaw_joint_X8" joint="right_hip_yaw_joint_X8" ctrlrange="-72 72" ctrllimited="true" />
    <motor name="right_knee_joint_X8" joint="right_knee_joint_X8" ctrlrange="-72 72" ctrllimited="true" />
    <motor name="right_ankle_pitch_joint_X4" joint="right_ankle_pitch_joint_X4" ctrlrange="-96.6 96.6" ctrllimited="true" />
    <motor name="right_ankle_roll_joint_X4" joint="right_ankle_roll_joint_X4" ctrlrange="-28.98 28.98" ctrllimited="true" />
  </actuator>
  <sensor>
    <force name="LeftFoot_fsensor" site="LeftFoot_site" />
    <torque name="LeftFoot_tsensor" site="LeftFoot_site" />
    <force name="RightFoot_fsensor" site="RightFoot_site" />
    <torque name="RightFoot_tsensor" site="RightFoot_site" />
    <gyro name="Default_gyro" site="Default_site" />
    <accelerometer name="Default_accelerometer" site="Default_site" />
    <gyro name="PelvisIMU_gyro" site="PelvisIMU_site" />
    <accelerometer name="PelvisIMU_accelerometer" site="PelvisIMU_site" />
    <gyro name="TorsoIMU_gyro" site="TorsoIMU_site" />
    <accelerometer name="TorsoIMU_accelerometer" site="TorsoIMU_site" />
    <gyro name="FloatingBase_gyro" site="Base_site" />
    <accelerometer name="FloatingBase_accelerometer" site="Base_site" />
  </sensor>
  <keyframe>
    <key name="home" qpos="0.0 0.0 1.208 1.0 0.0 0.0 0.0 0.0 0.0 0.0 0.0 0.0 0.0 0.0 0.0 0.0 0.0 0.0 0.0 0.0 -0.15 0.0 0.0 0.3 -0.15 0.0 -0.15 0.0 0.0 0.3 -0.15 0.0" />
  </keyframe>
</mujoco>